Workbook

Sheet MasterSheet
C1: جامعةالبصرة | G1: صفحة 1 من 5 | AF1: القسم:الفيزياء
C2: كليةالتربية الصرفة | AF2: المرحلـــــة:الثانية
AF3: الفصـــــــل : (سنوي)
G4: سجل الدرجات النهائية للسنة الدراسية2024-2025
B5: التسلسل | C5: الوحدات | D5: الجنس | E5: 7 | G5: 2 | I5: 6 | K5: 7 | M5: 4 | O5: 2 | Q5: 4 | S5: 4 | U5: 2 | W5: 0 | Y5: 3 | AA5: النتيجة | AB5: المعدل | AC5: التقدير | AD5: الترتيب | AE5: المعدل المرحلة% | AF5: الملاحظات
C6: اسم الطالب المواضيع | E6: الكهربائية والمغناطيسية | G6: اللغة العربية | I6: الرياضيات | K6: الميكانيك | M6: علم النفس | O6: الحاسبات | Q6: الحرارة وخواص المادة | S6: اسس التربية | U6: حقوق الانسان و الديمقراطية | W6: التربية الرياضية | Y6: حقوق الانسان و الديمقراطية
B7: 1 | C7: ابراهيم صباح لملوم شده | D7: ذ | F7: =IF(E7>=90,"م",IF(E7>=80,"جـ جـ",IF(E7>=70,"جـ",IF(E7>=60,"ط",IF(E7>=50,"ل","ر"))))) -> 0 | H7: =IF(G7>=90,"م",IF(G7>=80,"جـ جـ",IF(G7>=70,"جـ",IF(G7>=60,"ط",IF(G7>=50,"ل","ر"))))) -> 0 | J7: =IF(I7>=90,"م",IF(I7>=80,"جـ جـ",IF(I7>=70,"جـ",IF(I7>=60,"ط",IF(I7>=50,"ل","ر"))))) -> 0 | L7: =IF(K7>=90,"م",IF(K7>=80,"جـ جـ",IF(K7>=70,"جـ",IF(K7>=60,"ط",IF(K7>=50,"ل","ر"))))) -> 0 | N7: =IF(M7>=90,"م",IF(M7>=80,"جـ جـ",IF(M7>=70,"جـ",IF(M7>=60,"ط",IF(M7>=50,"ل","ر"))))) -> 0 | P7: =IF(O7>=90,"م",IF(O7>=80,"جـ جـ",IF(O7>=70,"جـ",IF(O7>=60,"ط",IF(O7>=50,"ل","ر"))))) -> 0 | R7: =IF(Q7>=90,"م",IF(Q7>=80,"جـ جـ",IF(Q7>=70,"جـ",IF(Q7>=60,"ط",IF(Q7>=50,"ل","ر"))))) -> 0 | T7: =IF(S7>=90,"م",IF(S7>=80,"جـ جـ",IF(S7>=70,"جـ",IF(S7>=60,"ط",IF(S7>=50,"ل","ر"))))) -> 0 | V7: =IF(U7>=90,"م",IF(U7>=80,"جـ جـ",IF(U7>=70,"جـ",IF(U7>=60,"ط",IF(U7>=50,"ل","ر"))))) -> 0 | X7: =IF(W7>=90,"م",IF(W7>=80,"جـ جـ",IF(W7>=70,"جـ",IF(W7>=60,"ط",IF(W7>=50,"ل","ر"))))) -> 0 | Z7: =IF(Y7>=90,"م",IF(Y7>=80,"جـ جـ",IF(Y7>=70,"جـ",IF(Y7>=60,"ط",IF(Y7>=50,"ل","ر"))))) -> 0 | AA7: =IF(AND(E7>=50, G7>=50, I7>=50, K7>=50, M7>=50, O7>=50, Q7>=50, S7>=50, U7>=50, W7>=50, Y7>=50), "ناجح", "راسب") -> 0 | AB7: =(E7*7 + G7*2 + I7*6 + K7*7 + M7*4 + O7*2 + Q7*4 + S7*4 + U7*2 + W7*0) / (7 + 2 + 6 + 7 + 4 + 2 + 4 + 4 + 2 + 0) -> 0 | AC7: =IF(AB7>=90,"امتياز",IF(AB7>=80,"جيد جدا",IF(AB7>=70,"جيد",IF(AB7>=60,"متوسط",IF(AB7>=50,"مقبول","راسب"))))) -> 0
B10: 2 | C10: احمد حسن كلخان موزان | D10: ذ | F10: =IF(E10>=90,"م",IF(E10>=80,"جـ جـ",IF(E10>=70,"جـ",IF(E10>=60,"ط",IF(E10>=50,"ل","ر"))))) -> 0 | H10: =IF(G10>=90,"م",IF(G10>=80,"جـ جـ",IF(G10>=70,"جـ",IF(G10>=60,"ط",IF(G10>=50,"ل","ر"))))) -> 0 | J10: =IF(I10>=90,"م",IF(I10>=80,"جـ جـ",IF(I10>=70,"جـ",IF(I10>=60,"ط",IF(I10>=50,"ل","ر"))))) -> 0 | L10: =IF(K10>=90,"م",IF(K10>=80,"جـ جـ",IF(K10>=70,"جـ",IF(K10>=60,"ط",IF(K10>=50,"ل","ر"))))) -> 0 | N10: =IF(M10>=90,"م",IF(M10>=80,"جـ جـ",IF(M10>=70,"جـ",IF(M10>=60,"ط",IF(M10>=50,"ل","ر"))))) -> 0 | P10: =IF(O10>=90,"م",IF(O10>=80,"جـ جـ",IF(O10>=70,"جـ",IF(O10>=60,"ط",IF(O10>=50,"ل","ر"))))) -> 0 | R10: =IF(Q10>=90,"م",IF(Q10>=80,"جـ جـ",IF(Q10>=70,"جـ",IF(Q10>=60,"ط",IF(Q10>=50,"ل","ر"))))) -> 0 | T10: =IF(S10>=90,"م",IF(S10>=80,"جـ جـ",IF(S10>=70,"جـ",IF(S10>=60,"ط",IF(S10>=50,"ل","ر"))))) -> 0 | V10: =IF(U10>=90,"م",IF(U10>=80,"جـ جـ",IF(U10>=70,"جـ",IF(U10>=60,"ط",IF(U10>=50,"ل","ر"))))) -> 0 | X10: =IF(W10>=90,"م",IF(W10>=80,"جـ جـ",IF(W10>=70,"جـ",IF(W10>=60,"ط",IF(W10>=50,"ل","ر"))))) -> 0 | Z10: =IF(Y10>=90,"م",IF(Y10>=80,"جـ جـ",IF(Y10>=70,"جـ",IF(Y10>=60,"ط",IF(Y10>=50,"ل","ر"))))) -> 0 | AA10: =IF(AND(E10>=50, G10>=50, I10>=50, K10>=50, M10>=50, O10>=50, Q10>=50, S10>=50, U10>=50, W10>=50, Y10>=50), "ناجح", "راسب") -> 0 | AB10: =(E10*7 + G10*2 + I10*6 + K10*7 + M10*4 + O10*2 + Q10*4 + S10*4 + U10*2 + W10*0) / (7 + 2 + 6 + 7 + 4 + 2 + 4 + 4 + 2 + 0) -> 0 | AC10: =IF(AB10>=90,"امتياز",IF(AB10>=80,"جيد جدا",IF(AB10>=70,"جيد",IF(AB10>=60,"متوسط",IF(AB10>=50,"مقبول","راسب"))))) -> 0
B13: 3 | C13: احمد شهاب احمد خميس | D13: ذ | F13: =IF(E13>=90,"م",IF(E13>=80,"جـ جـ",IF(E13>=70,"جـ",IF(E13>=60,"ط",IF(E13>=50,"ل","ر"))))) -> 0 | H13: =IF(G13>=90,"م",IF(G13>=80,"جـ جـ",IF(G13>=70,"جـ",IF(G13>=60,"ط",IF(G13>=50,"ل","ر"))))) -> 0 | J13: =IF(I13>=90,"م",IF(I13>=80,"جـ جـ",IF(I13>=70,"جـ",IF(I13>=60,"ط",IF(I13>=50,"ل","ر"))))) -> 0 | L13: =IF(K13>=90,"م",IF(K13>=80,"جـ جـ",IF(K13>=70,"جـ",IF(K13>=60,"ط",IF(K13>=50,"ل","ر"))))) -> 0 | N13: =IF(M13>=90,"م",IF(M13>=80,"جـ جـ",IF(M13>=70,"جـ",IF(M13>=60,"ط",IF(M13>=50,"ل","ر"))))) -> 0 | P13: =IF(O13>=90,"م",IF(O13>=80,"جـ جـ",IF(O13>=70,"جـ",IF(O13>=60,"ط",IF(O13>=50,"ل","ر"))))) -> 0 | R13: =IF(Q13>=90,"م",IF(Q13>=80,"جـ جـ",IF(Q13>=70,"جـ",IF(Q13>=60,"ط",IF(Q13>=50,"ل","ر"))))) -> 0 | T13: =IF(S13>=90,"م",IF(S13>=80,"جـ جـ",IF(S13>=70,"جـ",IF(S13>=60,"ط",IF(S13>=50,"ل","ر"))))) -> 0 | V13: =IF(U13>=90,"م",IF(U13>=80,"جـ جـ",IF(U13>=70,"جـ",IF(U13>=60,"ط",IF(U13>=50,"ل","ر"))))) -> 0 | X13: =IF(W13>=90,"م",IF(W13>=80,"جـ جـ",IF(W13>=70,"جـ",IF(W13>=60,"ط",IF(W13>=50,"ل","ر"))))) -> 0 | Z13: =IF(Y13>=90,"م",IF(Y13>=80,"جـ جـ",IF(Y13>=70,"جـ",IF(Y13>=60,"ط",IF(Y13>=50,"ل","ر"))))) -> 0 | AA13: =IF(AND(E13>=50, G13>=50, I13>=50, K13>=50, M13>=50, O13>=50, Q13>=50, S13>=50, U13>=50, W13>=50, Y13>=50), "ناجح", "راسب") -> 0 | AB13: =(E13*7 + G13*2 + I13*6 + K13*7 + M13*4 + O13*2 + Q13*4 + S13*4 + U13*2 + W13*0) / (7 + 2 + 6 + 7 + 4 + 2 + 4 + 4 + 2 + 0) -> 0 | AC13: =IF(AB13>=90,"امتياز",IF(AB13>=80,"جيد جدا",IF(AB13>=70,"جيد",IF(AB13>=60,"متوسط",IF(AB13>=50,"مقبول","راسب"))))) -> 0
B16: 4 | C16: احمد طالب ثجيل هادي | D16: ذ | F16: =IF(E16>=90,"م",IF(E16>=80,"جـ جـ",IF(E16>=70,"جـ",IF(E16>=60,"ط",IF(E16>=50,"ل","ر"))))) -> 0 | H16: =IF(G16>=90,"م",IF(G16>=80,"جـ جـ",IF(G16>=70,"جـ",IF(G16>=60,"ط",IF(G16>=50,"ل","ر"))))) -> 0 | J16: =IF(I16>=90,"م",IF(I16>=80,"جـ جـ",IF(I16>=70,"جـ",IF(I16>=60,"ط",IF(I16>=50,"ل","ر"))))) -> 0 | L16: =IF(K16>=90,"م",IF(K16>=80,"جـ جـ",IF(K16>=70,"جـ",IF(K16>=60,"ط",IF(K16>=50,"ل","ر"))))) -> 0 | N16: =IF(M16>=90,"م",IF(M16>=80,"جـ جـ",IF(M16>=70,"جـ",IF(M16>=60,"ط",IF(M16>=50,"ل","ر"))))) -> 0 | P16: =IF(O16>=90,"م",IF(O16>=80,"جـ جـ",IF(O16>=70,"جـ",IF(O16>=60,"ط",IF(O16>=50,"ل","ر"))))) -> 0 | R16: =IF(Q16>=90,"م",IF(Q16>=80,"جـ جـ",IF(Q16>=70,"جـ",IF(Q16>=60,"ط",IF(Q16>=50,"ل","ر"))))) -> 0 | T16: =IF(S16>=90,"م",IF(S16>=80,"جـ جـ",IF(S16>=70,"جـ",IF(S16>=60,"ط",IF(S16>=50,"ل","ر"))))) -> 0 | V16: =IF(U16>=90,"م",IF(U16>=80,"جـ جـ",IF(U16>=70,"جـ",IF(U16>=60,"ط",IF(U16>=50,"ل","ر"))))) -> 0 | X16: =IF(W16>=90,"م",IF(W16>=80,"جـ جـ",IF(W16>=70,"جـ",IF(W16>=60,"ط",IF(W16>=50,"ل","ر"))))) -> 0 | Z16: =IF(Y16>=90,"م",IF(Y16>=80,"جـ جـ",IF(Y16>=70,"جـ",IF(Y16>=60,"ط",IF(Y16>=50,"ل","ر"))))) -> 0 | AA16: =IF(AND(E16>=50, G16>=50, I16>=50, K16>=50, M16>=50, O16>=50, Q16>=50, S16>=50, U16>=50, W16>=50, Y16>=50), "ناجح", "راسب") -> 0 | AB16: =(E16*7 + G16*2 + I16*6 + K16*7 + M16*4 + O16*2 + Q16*4 + S16*4 + U16*2 + W16*0) / (7 + 2 + 6 + 7 + 4 + 2 + 4 + 4 + 2 + 0) -> 0 | AC16: =IF(AB16>=90,"امتياز",IF(AB16>=80,"جيد جدا",IF(AB16>=70,"جيد",IF(AB16>=60,"متوسط",IF(AB16>=50,"مقبول","راسب"))))) -> 0
B19: 5 | C19: احمد عماد ثجيل عبد | D19: ذ | F19: =IF(E19>=90,"م",IF(E19>=80,"جـ جـ",IF(E19>=70,"جـ",IF(E19>=60,"ط",IF(E19>=50,"ل","ر"))))) -> 0 | H19: =IF(G19>=90,"م",IF(G19>=80,"جـ جـ",IF(G19>=70,"جـ",IF(G19>=60,"ط",IF(G19>=50,"ل","ر"))))) -> 0 | J19: =IF(I19>=90,"م",IF(I19>=80,"جـ جـ",IF(I19>=70,"جـ",IF(I19>=60,"ط",IF(I19>=50,"ل","ر"))))) -> 0 | L19: =IF(K19>=90,"م",IF(K19>=80,"جـ جـ",IF(K19>=70,"جـ",IF(K19>=60,"ط",IF(K19>=50,"ل","ر"))))) -> 0 | N19: =IF(M19>=90,"م",IF(M19>=80,"جـ جـ",IF(M19>=70,"جـ",IF(M19>=60,"ط",IF(M19>=50,"ل","ر"))))) -> 0 | P19: =IF(O19>=90,"م",IF(O19>=80,"جـ جـ",IF(O19>=70,"جـ",IF(O19>=60,"ط",IF(O19>=50,"ل","ر"))))) -> 0 | R19: =IF(Q19>=90,"م",IF(Q19>=80,"جـ جـ",IF(Q19>=70,"جـ",IF(Q19>=60,"ط",IF(Q19>=50,"ل","ر"))))) -> 0 | T19: =IF(S19>=90,"م",IF(S19>=80,"جـ جـ",IF(S19>=70,"جـ",IF(S19>=60,"ط",IF(S19>=50,"ل","ر"))))) -> 0 | V19: =IF(U19>=90,"م",IF(U19>=80,"جـ جـ",IF(U19>=70,"جـ",IF(U19>=60,"ط",IF(U19>=50,"ل","ر"))))) -> 0 | X19: =IF(W19>=90,"م",IF(W19>=80,"جـ جـ",IF(W19>=70,"جـ",IF(W19>=60,"ط",IF(W19>=50,"ل","ر"))))) -> 0 | Z19: =IF(Y19>=90,"م",IF(Y19>=80,"جـ جـ",IF(Y19>=70,"جـ",IF(Y19>=60,"ط",IF(Y19>=50,"ل","ر"))))) -> 0 | AA19: =IF(AND(E19>=50, G19>=50, I19>=50, K19>=50, M19>=50, O19>=50, Q19>=50, S19>=50, U19>=50, W19>=50, Y19>=50), "ناجح", "راسب") -> 0 | AB19: =(E19*7 + G19*2 + I19*6 + K19*7 + M19*4 + O19*2 + Q19*4 + S19*4 + U19*2 + W19*0) / (7 + 2 + 6 + 7 + 4 + 2 + 4 + 4 + 2 + 0) -> 0 | AC19: =IF(AB19>=90,"امتياز",IF(AB19>=80,"جيد جدا",IF(AB19>=70,"جيد",IF(AB19>=60,"متوسط",IF(AB19>=50,"مقبول","راسب"))))) -> 0
B22: 6 | C22: احمد فلاح حسن جبر | D22: ذ | F22: =IF(E22>=90,"م",IF(E22>=80,"جـ جـ",IF(E22>=70,"جـ",IF(E22>=60,"ط",IF(E22>=50,"ل","ر"))))) -> 0 | H22: =IF(G22>=90,"م",IF(G22>=80,"جـ جـ",IF(G22>=70,"جـ",IF(G22>=60,"ط",IF(G22>=50,"ل","ر"))))) -> 0 | J22: =IF(I22>=90,"م",IF(I22>=80,"جـ جـ",IF(I22>=70,"جـ",IF(I22>=60,"ط",IF(I22>=50,"ل","ر"))))) -> 0 | L22: =IF(K22>=90,"م",IF(K22>=80,"جـ جـ",IF(K22>=70,"جـ",IF(K22>=60,"ط",IF(K22>=50,"ل","ر"))))) -> 0 | N22: =IF(M22>=90,"م",IF(M22>=80,"جـ جـ",IF(M22>=70,"جـ",IF(M22>=60,"ط",IF(M22>=50,"ل","ر"))))) -> 0 | P22: =IF(O22>=90,"م",IF(O22>=80,"جـ جـ",IF(O22>=70,"جـ",IF(O22>=60,"ط",IF(O22>=50,"ل","ر"))))) -> 0 | R22: =IF(Q22>=90,"م",IF(Q22>=80,"جـ جـ",IF(Q22>=70,"جـ",IF(Q22>=60,"ط",IF(Q22>=50,"ل","ر"))))) -> 0 | T22: =IF(S22>=90,"م",IF(S22>=80,"جـ جـ",IF(S22>=70,"جـ",IF(S22>=60,"ط",IF(S22>=50,"ل","ر"))))) -> 0 | V22: =IF(U22>=90,"م",IF(U22>=80,"جـ جـ",IF(U22>=70,"جـ",IF(U22>=60,"ط",IF(U22>=50,"ل","ر"))))) -> 0 | X22: =IF(W22>=90,"م",IF(W22>=80,"جـ جـ",IF(W22>=70,"جـ",IF(W22>=60,"ط",IF(W22>=50,"ل","ر"))))) -> 0 | Z22: =IF(Y22>=90,"م",IF(Y22>=80,"جـ جـ",IF(Y22>=70,"جـ",IF(Y22>=60,"ط",IF(Y22>=50,"ل","ر"))))) -> 0 | AA22: =IF(AND(E22>=50, G22>=50, I22>=50, K22>=50, M22>=50, O22>=50, Q22>=50, S22>=50, U22>=50, W22>=50, Y22>=50), "ناجح", "راسب") -> 0 | AB22: =(E22*7 + G22*2 + I22*6 + K22*7 + M22*4 + O22*2 + Q22*4 + S22*4 + U22*2 + W22*0) / (7 + 2 + 6 + 7 + 4 + 2 + 4 + 4 + 2 + 0) -> 0 | AC22: =IF(AB22>=90,"امتياز",IF(AB22>=80,"جيد جدا",IF(AB22>=70,"جيد",IF(AB22>=60,"متوسط",IF(AB22>=50,"مقبول","راسب"))))) -> 0
B25: 7 | C25: اديان صالح مهدي عاتي | D25: ذ | F25: =IF(E25>=90,"م",IF(E25>=80,"جـ جـ",IF(E25>=70,"جـ",IF(E25>=60,"ط",IF(E25>=50,"ل","ر"))))) -> 0 | H25: =IF(G25>=90,"م",IF(G25>=80,"جـ جـ",IF(G25>=70,"جـ",IF(G25>=60,"ط",IF(G25>=50,"ل","ر"))))) -> 0 | J25: =IF(I25>=90,"م",IF(I25>=80,"جـ جـ",IF(I25>=70,"جـ",IF(I25>=60,"ط",IF(I25>=50,"ل","ر"))))) -> 0 | L25: =IF(K25>=90,"م",IF(K25>=80,"جـ جـ",IF(K25>=70,"جـ",IF(K25>=60,"ط",IF(K25>=50,"ل","ر"))))) -> 0 | N25: =IF(M25>=90,"م",IF(M25>=80,"جـ جـ",IF(M25>=70,"جـ",IF(M25>=60,"ط",IF(M25>=50,"ل","ر"))))) -> 0 | P25: =IF(O25>=90,"م",IF(O25>=80,"جـ جـ",IF(O25>=70,"جـ",IF(O25>=60,"ط",IF(O25>=50,"ل","ر"))))) -> 0 | R25: =IF(Q25>=90,"م",IF(Q25>=80,"جـ جـ",IF(Q25>=70,"جـ",IF(Q25>=60,"ط",IF(Q25>=50,"ل","ر"))))) -> 0 | T25: =IF(S25>=90,"م",IF(S25>=80,"جـ جـ",IF(S25>=70,"جـ",IF(S25>=60,"ط",IF(S25>=50,"ل","ر"))))) -> 0 | V25: =IF(U25>=90,"م",IF(U25>=80,"جـ جـ",IF(U25>=70,"جـ",IF(U25>=60,"ط",IF(U25>=50,"ل","ر"))))) -> 0 | X25: =IF(W25>=90,"م",IF(W25>=80,"جـ جـ",IF(W25>=70,"جـ",IF(W25>=60,"ط",IF(W25>=50,"ل","ر"))))) -> 0 | Z25: =IF(Y25>=90,"م",IF(Y25>=80,"جـ جـ",IF(Y25>=70,"جـ",IF(Y25>=60,"ط",IF(Y25>=50,"ل","ر"))))) -> 0 | AA25: =IF(AND(E25>=50, G25>=50, I25>=50, K25>=50, M25>=50, O25>=50, Q25>=50, S25>=50, U25>=50, W25>=50, Y25>=50), "ناجح", "راسب") -> 0 | AB25: =(E25*7 + G25*2 + I25*6 + K25*7 + M25*4 + O25*2 + Q25*4 + S25*4 + U25*2 + W25*0) / (7 + 2 + 6 + 7 + 4 + 2 + 4 + 4 + 2 + 0) -> 0 | AC25: =IF(AB25>=90,"امتياز",IF(AB25>=80,"جيد جدا",IF(AB25>=70,"جيد",IF(AB25>=60,"متوسط",IF(AB25>=50,"مقبول","راسب"))))) -> 0
B28: 8 | C28: ارشد صلاح جواد حسن | D28: ذ | F28: =IF(E28>=90,"م",IF(E28>=80,"جـ جـ",IF(E28>=70,"جـ",IF(E28>=60,"ط",IF(E28>=50,"ل","ر"))))) -> 0 | H28: =IF(G28>=90,"م",IF(G28>=80,"جـ جـ",IF(G28>=70,"جـ",IF(G28>=60,"ط",IF(G28>=50,"ل","ر"))))) -> 0 | J28: =IF(I28>=90,"م",IF(I28>=80,"جـ جـ",IF(I28>=70,"جـ",IF(I28>=60,"ط",IF(I28>=50,"ل","ر"))))) -> 0 | L28: =IF(K28>=90,"م",IF(K28>=80,"جـ جـ",IF(K28>=70,"جـ",IF(K28>=60,"ط",IF(K28>=50,"ل","ر"))))) -> 0 | N28: =IF(M28>=90,"م",IF(M28>=80,"جـ جـ",IF(M28>=70,"جـ",IF(M28>=60,"ط",IF(M28>=50,"ل","ر"))))) -> 0 | P28: =IF(O28>=90,"م",IF(O28>=80,"جـ جـ",IF(O28>=70,"جـ",IF(O28>=60,"ط",IF(O28>=50,"ل","ر"))))) -> 0 | R28: =IF(Q28>=90,"م",IF(Q28>=80,"جـ جـ",IF(Q28>=70,"جـ",IF(Q28>=60,"ط",IF(Q28>=50,"ل","ر"))))) -> 0 | T28: =IF(S28>=90,"م",IF(S28>=80,"جـ جـ",IF(S28>=70,"جـ",IF(S28>=60,"ط",IF(S28>=50,"ل","ر"))))) -> 0 | V28: =IF(U28>=90,"م",IF(U28>=80,"جـ جـ",IF(U28>=70,"جـ",IF(U28>=60,"ط",IF(U28>=50,"ل","ر"))))) -> 0 | X28: =IF(W28>=90,"م",IF(W28>=80,"جـ جـ",IF(W28>=70,"جـ",IF(W28>=60,"ط",IF(W28>=50,"ل","ر"))))) -> 0 | Z28: =IF(Y28>=90,"م",IF(Y28>=80,"جـ جـ",IF(Y28>=70,"جـ",IF(Y28>=60,"ط",IF(Y28>=50,"ل","ر"))))) -> 0 | AA28: =IF(AND(E28>=50, G28>=50, I28>=50, K28>=50, M28>=50, O28>=50, Q28>=50, S28>=50, U28>=50, W28>=50, Y28>=50), "ناجح", "راسب") -> 0 | AB28: =(E28*7 + G28*2 + I28*6 + K28*7 + M28*4 + O28*2 + Q28*4 + S28*4 + U28*2 + W28*0) / (7 + 2 + 6 + 7 + 4 + 2 + 4 + 4 + 2 + 0) -> 0 | AC28: =IF(AB28>=90,"امتياز",IF(AB28>=80,"جيد جدا",IF(AB28>=70,"جيد",IF(AB28>=60,"متوسط",IF(AB28>=50,"مقبول","راسب"))))) -> 0
B31: 9 | C31: استبرق عبدالمنعم كاظم محمد | D31: ذ | F31: =IF(E31>=90,"م",IF(E31>=80,"جـ جـ",IF(E31>=70,"جـ",IF(E31>=60,"ط",IF(E31>=50,"ل","ر"))))) -> 0 | H31: =IF(G31>=90,"م",IF(G31>=80,"جـ جـ",IF(G31>=70,"جـ",IF(G31>=60,"ط",IF(G31>=50,"ل","ر"))))) -> 0 | J31: =IF(I31>=90,"م",IF(I31>=80,"جـ جـ",IF(I31>=70,"جـ",IF(I31>=60,"ط",IF(I31>=50,"ل","ر"))))) -> 0 | L31: =IF(K31>=90,"م",IF(K31>=80,"جـ جـ",IF(K31>=70,"جـ",IF(K31>=60,"ط",IF(K31>=50,"ل","ر"))))) -> 0 | N31: =IF(M31>=90,"م",IF(M31>=80,"جـ جـ",IF(M31>=70,"جـ",IF(M31>=60,"ط",IF(M31>=50,"ل","ر"))))) -> 0 | P31: =IF(O31>=90,"م",IF(O31>=80,"جـ جـ",IF(O31>=70,"جـ",IF(O31>=60,"ط",IF(O31>=50,"ل","ر"))))) -> 0 | R31: =IF(Q31>=90,"م",IF(Q31>=80,"جـ جـ",IF(Q31>=70,"جـ",IF(Q31>=60,"ط",IF(Q31>=50,"ل","ر"))))) -> 0 | T31: =IF(S31>=90,"م",IF(S31>=80,"جـ جـ",IF(S31>=70,"جـ",IF(S31>=60,"ط",IF(S31>=50,"ل","ر"))))) -> 0 | V31: =IF(U31>=90,"م",IF(U31>=80,"جـ جـ",IF(U31>=70,"جـ",IF(U31>=60,"ط",IF(U31>=50,"ل","ر"))))) -> 0 | X31: =IF(W31>=90,"م",IF(W31>=80,"جـ جـ",IF(W31>=70,"جـ",IF(W31>=60,"ط",IF(W31>=50,"ل","ر"))))) -> 0 | Z31: =IF(Y31>=90,"م",IF(Y31>=80,"جـ جـ",IF(Y31>=70,"جـ",IF(Y31>=60,"ط",IF(Y31>=50,"ل","ر"))))) -> 0 | AA31: =IF(AND(E31>=50, G31>=50, I31>=50, K31>=50, M31>=50, O31>=50, Q31>=50, S31>=50, U31>=50, W31>=50, Y31>=50), "ناجح", "راسب") -> 0 | AB31: =(E31*7 + G31*2 + I31*6 + K31*7 + M31*4 + O31*2 + Q31*4 + S31*4 + U31*2 + W31*0) / (7 + 2 + 6 + 7 + 4 + 2 + 4 + 4 + 2 + 0) -> 0 | AC31: =IF(AB31>=90,"امتياز",IF(AB31>=80,"جيد جدا",IF(AB31>=70,"جيد",IF(AB31>=60,"متوسط",IF(AB31>=50,"مقبول","راسب"))))) -> 0
B34: 10 | C34: اطياف حامد سالم مجيد | D34: ذ | F34: =IF(E34>=90,"م",IF(E34>=80,"جـ جـ",IF(E34>=70,"جـ",IF(E34>=60,"ط",IF(E34>=50,"ل","ر"))))) -> 0 | H34: =IF(G34>=90,"م",IF(G34>=80,"جـ جـ",IF(G34>=70,"جـ",IF(G34>=60,"ط",IF(G34>=50,"ل","ر"))))) -> 0 | J34: =IF(I34>=90,"م",IF(I34>=80,"جـ جـ",IF(I34>=70,"جـ",IF(I34>=60,"ط",IF(I34>=50,"ل","ر"))))) -> 0 | L34: =IF(K34>=90,"م",IF(K34>=80,"جـ جـ",IF(K34>=70,"جـ",IF(K34>=60,"ط",IF(K34>=50,"ل","ر"))))) -> 0 | N34: =IF(M34>=90,"م",IF(M34>=80,"جـ جـ",IF(M34>=70,"جـ",IF(M34>=60,"ط",IF(M34>=50,"ل","ر"))))) -> 0 | P34: =IF(O34>=90,"م",IF(O34>=80,"جـ جـ",IF(O34>=70,"جـ",IF(O34>=60,"ط",IF(O34>=50,"ل","ر"))))) -> 0 | R34: =IF(Q34>=90,"م",IF(Q34>=80,"جـ جـ",IF(Q34>=70,"جـ",IF(Q34>=60,"ط",IF(Q34>=50,"ل","ر"))))) -> 0 | T34: =IF(S34>=90,"م",IF(S34>=80,"جـ جـ",IF(S34>=70,"جـ",IF(S34>=60,"ط",IF(S34>=50,"ل","ر"))))) -> 0 | V34: =IF(U34>=90,"م",IF(U34>=80,"جـ جـ",IF(U34>=70,"جـ",IF(U34>=60,"ط",IF(U34>=50,"ل","ر"))))) -> 0 | X34: =IF(W34>=90,"م",IF(W34>=80,"جـ جـ",IF(W34>=70,"جـ",IF(W34>=60,"ط",IF(W34>=50,"ل","ر"))))) -> 0 | Z34: =IF(Y34>=90,"م",IF(Y34>=80,"جـ جـ",IF(Y34>=70,"جـ",IF(Y34>=60,"ط",IF(Y34>=50,"ل","ر"))))) -> 0 | AA34: =IF(AND(E34>=50, G34>=50, I34>=50, K34>=50, M34>=50, O34>=50, Q34>=50, S34>=50, U34>=50, W34>=50, Y34>=50), "ناجح", "راسب") -> 0 | AB34: =(E34*7 + G34*2 + I34*6 + K34*7 + M34*4 + O34*2 + Q34*4 + S34*4 + U34*2 + W34*0) / (7 + 2 + 6 + 7 + 4 + 2 + 4 + 4 + 2 + 0) -> 0 | AC34: =IF(AB34>=90,"امتياز",IF(AB34>=80,"جيد جدا",IF(AB34>=70,"جيد",IF(AB34>=60,"متوسط",IF(AB34>=50,"مقبول","راسب"))))) -> 0
C38: اعضاء اللجنة الامتحانية:
C39: عضو اللجنة رقم 1 | F39: عضو اللجنة رقم 4 | K39: عضو اللجنة رقم 7 | P39: عضو اللجنة رقم 10 | W39: عضو اللجنة المركزية | AB39: عضو اللجنة المركزية | AF39: رئيس اللجنة المركزية
C40: عضو اللجنة رقم 2 | F40: عضو اللجنة رقم 5 | K40: عضو اللجنة رقم 8 | P40: عضو اللجنة رقم 11 | W40: اسم رئيس القسم | AB40: اسم المعاون العلمي | AF40: اسم عميد الكلية
C41: عضو اللجنة رقم 3 | F41: عضو اللجنة رقم 6 | K41: عضو اللجنة رقم 9 | P41: عضو اللجنة رقم 12
B43: 1 | C43: يمثل الحقل الاول ازاء اسم الطالب درجات الدور الاول و الذي يليه الدور الثاني و الحقل الثالث الاستحقاق
B44: 2 | C44: يثبت ازاء اسم الطالب سنة الرسوب ويوضع خط احمر تحت اسمه وتثبت درجات المواد غير المطالب بها لنجاحه في سنة سابقة بحبر اخضر
B45: 3 | C45: ل= مقبول ، ط= متوسط ، جـ= جيد ، جـ جـ = جيد جداً ، م = امتياز
C51: جامعةالبصرة | G51: صفحة 2 من 5 | AF51: القسم:الفيزياء
C52: كليةالتربية الصرفة | AF52: المرحلـــــة:الثانية
AF53: الفصـــــــل : (سنوي)
G54: سجل الدرجات النهائية للسنة الدراسية2024-2025
B55: التسلسل | C55: الوحدات | D55: الجنس | E55: 7 | G55: 2 | I55: 6 | K55: 7 | M55: 4 | O55: 2 | Q55: 4 | S55: 4 | U55: 2 | W55: 0 | Y55: 3 | AA55: النتيجة | AB55: المعدل | AC55: التقدير | AD55: الترتيب | AE55: المعدل المرحلة% | AF55: الملاحظات
C56: اسم الطالب المواضيع | E56: الكهربائية والمغناطيسية | G56: اللغة العربية | I56: الرياضيات | K56: الميكانيك | M56: علم النفس | O56: الحاسبات | Q56: الحرارة وخواص المادة | S56: اسس التربية | U56: حقوق الانسان و الديمقراطية | W56: التربية الرياضية | Y56: حقوق الانسان و الديمقراطية
B57: 11 | C57: انعام قاسم محمد علي صالح | D57: ذ | F57: =IF(E57>=90,"م",IF(E57>=80,"جـ جـ",IF(E57>=70,"جـ",IF(E57>=60,"ط",IF(E57>=50,"ل","ر"))))) -> 0 | H57: =IF(G57>=90,"م",IF(G57>=80,"جـ جـ",IF(G57>=70,"جـ",IF(G57>=60,"ط",IF(G57>=50,"ل","ر"))))) -> 0 | J57: =IF(I57>=90,"م",IF(I57>=80,"جـ جـ",IF(I57>=70,"جـ",IF(I57>=60,"ط",IF(I57>=50,"ل","ر"))))) -> 0 | L57: =IF(K57>=90,"م",IF(K57>=80,"جـ جـ",IF(K57>=70,"جـ",IF(K57>=60,"ط",IF(K57>=50,"ل","ر"))))) -> 0 | N57: =IF(M57>=90,"م",IF(M57>=80,"جـ جـ",IF(M57>=70,"جـ",IF(M57>=60,"ط",IF(M57>=50,"ل","ر"))))) -> 0 | P57: =IF(O57>=90,"م",IF(O57>=80,"جـ جـ",IF(O57>=70,"جـ",IF(O57>=60,"ط",IF(O57>=50,"ل","ر"))))) -> 0 | R57: =IF(Q57>=90,"م",IF(Q57>=80,"جـ جـ",IF(Q57>=70,"جـ",IF(Q57>=60,"ط",IF(Q57>=50,"ل","ر"))))) -> 0 | T57: =IF(S57>=90,"م",IF(S57>=80,"جـ جـ",IF(S57>=70,"جـ",IF(S57>=60,"ط",IF(S57>=50,"ل","ر"))))) -> 0 | V57: =IF(U57>=90,"م",IF(U57>=80,"جـ جـ",IF(U57>=70,"جـ",IF(U57>=60,"ط",IF(U57>=50,"ل","ر"))))) -> 0 | X57: =IF(W57>=90,"م",IF(W57>=80,"جـ جـ",IF(W57>=70,"جـ",IF(W57>=60,"ط",IF(W57>=50,"ل","ر"))))) -> 0 | Z57: =IF(Y57>=90,"م",IF(Y57>=80,"جـ جـ",IF(Y57>=70,"جـ",IF(Y57>=60,"ط",IF(Y57>=50,"ل","ر"))))) -> 0 | AA57: =IF(AND(E57>=50, G57>=50, I57>=50, K57>=50, M57>=50, O57>=50, Q57>=50, S57>=50, U57>=50, W57>=50, Y57>=50), "ناجح", "راسب") -> 0 | AB57: =(E57*7 + G57*2 + I57*6 + K57*7 + M57*4 + O57*2 + Q57*4 + S57*4 + U57*2 + W57*0) / (7 + 2 + 6 + 7 + 4 + 2 + 4 + 4 + 2 + 0) -> 0 | AC57: =IF(AB57>=90,"امتياز",IF(AB57>=80,"جيد جدا",IF(AB57>=70,"جيد",IF(AB57>=60,"متوسط",IF(AB57>=50,"مقبول","راسب"))))) -> 0
B60: 12 | C60: انور رحيم خميس حسن | D60: ذ | F60: =IF(E60>=90,"م",IF(E60>=80,"جـ جـ",IF(E60>=70,"جـ",IF(E60>=60,"ط",IF(E60>=50,"ل","ر"))))) -> 0 | H60: =IF(G60>=90,"م",IF(G60>=80,"جـ جـ",IF(G60>=70,"جـ",IF(G60>=60,"ط",IF(G60>=50,"ل","ر"))))) -> 0 | J60: =IF(I60>=90,"م",IF(I60>=80,"جـ جـ",IF(I60>=70,"جـ",IF(I60>=60,"ط",IF(I60>=50,"ل","ر"))))) -> 0 | L60: =IF(K60>=90,"م",IF(K60>=80,"جـ جـ",IF(K60>=70,"جـ",IF(K60>=60,"ط",IF(K60>=50,"ل","ر"))))) -> 0 | N60: =IF(M60>=90,"م",IF(M60>=80,"جـ جـ",IF(M60>=70,"جـ",IF(M60>=60,"ط",IF(M60>=50,"ل","ر"))))) -> 0 | P60: =IF(O60>=90,"م",IF(O60>=80,"جـ جـ",IF(O60>=70,"جـ",IF(O60>=60,"ط",IF(O60>=50,"ل","ر"))))) -> 0 | R60: =IF(Q60>=90,"م",IF(Q60>=80,"جـ جـ",IF(Q60>=70,"جـ",IF(Q60>=60,"ط",IF(Q60>=50,"ل","ر"))))) -> 0 | T60: =IF(S60>=90,"م",IF(S60>=80,"جـ جـ",IF(S60>=70,"جـ",IF(S60>=60,"ط",IF(S60>=50,"ل","ر"))))) -> 0 | V60: =IF(U60>=90,"م",IF(U60>=80,"جـ جـ",IF(U60>=70,"جـ",IF(U60>=60,"ط",IF(U60>=50,"ل","ر"))))) -> 0 | X60: =IF(W60>=90,"م",IF(W60>=80,"جـ جـ",IF(W60>=70,"جـ",IF(W60>=60,"ط",IF(W60>=50,"ل","ر"))))) -> 0 | Z60: =IF(Y60>=90,"م",IF(Y60>=80,"جـ جـ",IF(Y60>=70,"جـ",IF(Y60>=60,"ط",IF(Y60>=50,"ل","ر"))))) -> 0 | AA60: =IF(AND(E60>=50, G60>=50, I60>=50, K60>=50, M60>=50, O60>=50, Q60>=50, S60>=50, U60>=50, W60>=50, Y60>=50), "ناجح", "راسب") -> 0 | AB60: =(E60*7 + G60*2 + I60*6 + K60*7 + M60*4 + O60*2 + Q60*4 + S60*4 + U60*2 + W60*0) / (7 + 2 + 6 + 7 + 4 + 2 + 4 + 4 + 2 + 0) -> 0 | AC60: =IF(AB60>=90,"امتياز",IF(AB60>=80,"جيد جدا",IF(AB60>=70,"جيد",IF(AB60>=60,"متوسط",IF(AB60>=50,"مقبول","راسب"))))) -> 0
B63: 13 | C63: ايمان زكي علي حسين | D63: ذ | F63: =IF(E63>=90,"م",IF(E63>=80,"جـ جـ",IF(E63>=70,"جـ",IF(E63>=60,"ط",IF(E63>=50,"ل","ر"))))) -> 0 | H63: =IF(G63>=90,"م",IF(G63>=80,"جـ جـ",IF(G63>=70,"جـ",IF(G63>=60,"ط",IF(G63>=50,"ل","ر"))))) -> 0 | J63: =IF(I63>=90,"م",IF(I63>=80,"جـ جـ",IF(I63>=70,"جـ",IF(I63>=60,"ط",IF(I63>=50,"ل","ر"))))) -> 0 | L63: =IF(K63>=90,"م",IF(K63>=80,"جـ جـ",IF(K63>=70,"جـ",IF(K63>=60,"ط",IF(K63>=50,"ل","ر"))))) -> 0 | N63: =IF(M63>=90,"م",IF(M63>=80,"جـ جـ",IF(M63>=70,"جـ",IF(M63>=60,"ط",IF(M63>=50,"ل","ر"))))) -> 0 | P63: =IF(O63>=90,"م",IF(O63>=80,"جـ جـ",IF(O63>=70,"جـ",IF(O63>=60,"ط",IF(O63>=50,"ل","ر"))))) -> 0 | R63: =IF(Q63>=90,"م",IF(Q63>=80,"جـ جـ",IF(Q63>=70,"جـ",IF(Q63>=60,"ط",IF(Q63>=50,"ل","ر"))))) -> 0 | T63: =IF(S63>=90,"م",IF(S63>=80,"جـ جـ",IF(S63>=70,"جـ",IF(S63>=60,"ط",IF(S63>=50,"ل","ر"))))) -> 0 | V63: =IF(U63>=90,"م",IF(U63>=80,"جـ جـ",IF(U63>=70,"جـ",IF(U63>=60,"ط",IF(U63>=50,"ل","ر"))))) -> 0 | X63: =IF(W63>=90,"م",IF(W63>=80,"جـ جـ",IF(W63>=70,"جـ",IF(W63>=60,"ط",IF(W63>=50,"ل","ر"))))) -> 0 | Z63: =IF(Y63>=90,"م",IF(Y63>=80,"جـ جـ",IF(Y63>=70,"جـ",IF(Y63>=60,"ط",IF(Y63>=50,"ل","ر"))))) -> 0 | AA63: =IF(AND(E63>=50, G63>=50, I63>=50, K63>=50, M63>=50, O63>=50, Q63>=50, S63>=50, U63>=50, W63>=50, Y63>=50), "ناجح", "راسب") -> 0 | AB63: =(E63*7 + G63*2 + I63*6 + K63*7 + M63*4 + O63*2 + Q63*4 + S63*4 + U63*2 + W63*0) / (7 + 2 + 6 + 7 + 4 + 2 + 4 + 4 + 2 + 0) -> 0 | AC63: =IF(AB63>=90,"امتياز",IF(AB63>=80,"جيد جدا",IF(AB63>=70,"جيد",IF(AB63>=60,"متوسط",IF(AB63>=50,"مقبول","راسب"))))) -> 0
B66: 14 | C66: ايمان مؤيد حسن عباس | D66: ذ | F66: =IF(E66>=90,"م",IF(E66>=80,"جـ جـ",IF(E66>=70,"جـ",IF(E66>=60,"ط",IF(E66>=50,"ل","ر"))))) -> 0 | H66: =IF(G66>=90,"م",IF(G66>=80,"جـ جـ",IF(G66>=70,"جـ",IF(G66>=60,"ط",IF(G66>=50,"ل","ر"))))) -> 0 | J66: =IF(I66>=90,"م",IF(I66>=80,"جـ جـ",IF(I66>=70,"جـ",IF(I66>=60,"ط",IF(I66>=50,"ل","ر"))))) -> 0 | L66: =IF(K66>=90,"م",IF(K66>=80,"جـ جـ",IF(K66>=70,"جـ",IF(K66>=60,"ط",IF(K66>=50,"ل","ر"))))) -> 0 | N66: =IF(M66>=90,"م",IF(M66>=80,"جـ جـ",IF(M66>=70,"جـ",IF(M66>=60,"ط",IF(M66>=50,"ل","ر"))))) -> 0 | P66: =IF(O66>=90,"م",IF(O66>=80,"جـ جـ",IF(O66>=70,"جـ",IF(O66>=60,"ط",IF(O66>=50,"ل","ر"))))) -> 0 | R66: =IF(Q66>=90,"م",IF(Q66>=80,"جـ جـ",IF(Q66>=70,"جـ",IF(Q66>=60,"ط",IF(Q66>=50,"ل","ر"))))) -> 0 | T66: =IF(S66>=90,"م",IF(S66>=80,"جـ جـ",IF(S66>=70,"جـ",IF(S66>=60,"ط",IF(S66>=50,"ل","ر"))))) -> 0 | V66: =IF(U66>=90,"م",IF(U66>=80,"جـ جـ",IF(U66>=70,"جـ",IF(U66>=60,"ط",IF(U66>=50,"ل","ر"))))) -> 0 | X66: =IF(W66>=90,"م",IF(W66>=80,"جـ جـ",IF(W66>=70,"جـ",IF(W66>=60,"ط",IF(W66>=50,"ل","ر"))))) -> 0 | Z66: =IF(Y66>=90,"م",IF(Y66>=80,"جـ جـ",IF(Y66>=70,"جـ",IF(Y66>=60,"ط",IF(Y66>=50,"ل","ر"))))) -> 0 | AA66: =IF(AND(E66>=50, G66>=50, I66>=50, K66>=50, M66>=50, O66>=50, Q66>=50, S66>=50, U66>=50, W66>=50, Y66>=50), "ناجح", "راسب") -> 0 | AB66: =(E66*7 + G66*2 + I66*6 + K66*7 + M66*4 + O66*2 + Q66*4 + S66*4 + U66*2 + W66*0) / (7 + 2 + 6 + 7 + 4 + 2 + 4 + 4 + 2 + 0) -> 0 | AC66: =IF(AB66>=90,"امتياز",IF(AB66>=80,"جيد جدا",IF(AB66>=70,"جيد",IF(AB66>=60,"متوسط",IF(AB66>=50,"مقبول","راسب"))))) -> 0
B69: 15 | C69: ايمن محمد رزاق صالح | D69: ذ | F69: =IF(E69>=90,"م",IF(E69>=80,"جـ جـ",IF(E69>=70,"جـ",IF(E69>=60,"ط",IF(E69>=50,"ل","ر"))))) -> 0 | H69: =IF(G69>=90,"م",IF(G69>=80,"جـ جـ",IF(G69>=70,"جـ",IF(G69>=60,"ط",IF(G69>=50,"ل","ر"))))) -> 0 | J69: =IF(I69>=90,"م",IF(I69>=80,"جـ جـ",IF(I69>=70,"جـ",IF(I69>=60,"ط",IF(I69>=50,"ل","ر"))))) -> 0 | L69: =IF(K69>=90,"م",IF(K69>=80,"جـ جـ",IF(K69>=70,"جـ",IF(K69>=60,"ط",IF(K69>=50,"ل","ر"))))) -> 0 | N69: =IF(M69>=90,"م",IF(M69>=80,"جـ جـ",IF(M69>=70,"جـ",IF(M69>=60,"ط",IF(M69>=50,"ل","ر"))))) -> 0 | P69: =IF(O69>=90,"م",IF(O69>=80,"جـ جـ",IF(O69>=70,"جـ",IF(O69>=60,"ط",IF(O69>=50,"ل","ر"))))) -> 0 | R69: =IF(Q69>=90,"م",IF(Q69>=80,"جـ جـ",IF(Q69>=70,"جـ",IF(Q69>=60,"ط",IF(Q69>=50,"ل","ر"))))) -> 0 | T69: =IF(S69>=90,"م",IF(S69>=80,"جـ جـ",IF(S69>=70,"جـ",IF(S69>=60,"ط",IF(S69>=50,"ل","ر"))))) -> 0 | V69: =IF(U69>=90,"م",IF(U69>=80,"جـ جـ",IF(U69>=70,"جـ",IF(U69>=60,"ط",IF(U69>=50,"ل","ر"))))) -> 0 | X69: =IF(W69>=90,"م",IF(W69>=80,"جـ جـ",IF(W69>=70,"جـ",IF(W69>=60,"ط",IF(W69>=50,"ل","ر"))))) -> 0 | Z69: =IF(Y69>=90,"م",IF(Y69>=80,"جـ جـ",IF(Y69>=70,"جـ",IF(Y69>=60,"ط",IF(Y69>=50,"ل","ر"))))) -> 0 | AA69: =IF(AND(E69>=50, G69>=50, I69>=50, K69>=50, M69>=50, O69>=50, Q69>=50, S69>=50, U69>=50, W69>=50, Y69>=50), "ناجح", "راسب") -> 0 | AB69: =(E69*7 + G69*2 + I69*6 + K69*7 + M69*4 + O69*2 + Q69*4 + S69*4 + U69*2 + W69*0) / (7 + 2 + 6 + 7 + 4 + 2 + 4 + 4 + 2 + 0) -> 0 | AC69: =IF(AB69>=90,"امتياز",IF(AB69>=80,"جيد جدا",IF(AB69>=70,"جيد",IF(AB69>=60,"متوسط",IF(AB69>=50,"مقبول","راسب"))))) -> 0
B72: 16 | C72: ايناس ثائر حسين كاظم | D72: ذ | F72: =IF(E72>=90,"م",IF(E72>=80,"جـ جـ",IF(E72>=70,"جـ",IF(E72>=60,"ط",IF(E72>=50,"ل","ر"))))) -> 0 | H72: =IF(G72>=90,"م",IF(G72>=80,"جـ جـ",IF(G72>=70,"جـ",IF(G72>=60,"ط",IF(G72>=50,"ل","ر"))))) -> 0 | J72: =IF(I72>=90,"م",IF(I72>=80,"جـ جـ",IF(I72>=70,"جـ",IF(I72>=60,"ط",IF(I72>=50,"ل","ر"))))) -> 0 | L72: =IF(K72>=90,"م",IF(K72>=80,"جـ جـ",IF(K72>=70,"جـ",IF(K72>=60,"ط",IF(K72>=50,"ل","ر"))))) -> 0 | N72: =IF(M72>=90,"م",IF(M72>=80,"جـ جـ",IF(M72>=70,"جـ",IF(M72>=60,"ط",IF(M72>=50,"ل","ر"))))) -> 0 | P72: =IF(O72>=90,"م",IF(O72>=80,"جـ جـ",IF(O72>=70,"جـ",IF(O72>=60,"ط",IF(O72>=50,"ل","ر"))))) -> 0 | R72: =IF(Q72>=90,"م",IF(Q72>=80,"جـ جـ",IF(Q72>=70,"جـ",IF(Q72>=60,"ط",IF(Q72>=50,"ل","ر"))))) -> 0 | T72: =IF(S72>=90,"م",IF(S72>=80,"جـ جـ",IF(S72>=70,"جـ",IF(S72>=60,"ط",IF(S72>=50,"ل","ر"))))) -> 0 | V72: =IF(U72>=90,"م",IF(U72>=80,"جـ جـ",IF(U72>=70,"جـ",IF(U72>=60,"ط",IF(U72>=50,"ل","ر"))))) -> 0 | X72: =IF(W72>=90,"م",IF(W72>=80,"جـ جـ",IF(W72>=70,"جـ",IF(W72>=60,"ط",IF(W72>=50,"ل","ر"))))) -> 0 | Z72: =IF(Y72>=90,"م",IF(Y72>=80,"جـ جـ",IF(Y72>=70,"جـ",IF(Y72>=60,"ط",IF(Y72>=50,"ل","ر"))))) -> 0 | AA72: =IF(AND(E72>=50, G72>=50, I72>=50, K72>=50, M72>=50, O72>=50, Q72>=50, S72>=50, U72>=50, W72>=50, Y72>=50), "ناجح", "راسب") -> 0 | AB72: =(E72*7 + G72*2 + I72*6 + K72*7 + M72*4 + O72*2 + Q72*4 + S72*4 + U72*2 + W72*0) / (7 + 2 + 6 + 7 + 4 + 2 + 4 + 4 + 2 + 0) -> 0 | AC72: =IF(AB72>=90,"امتياز",IF(AB72>=80,"جيد جدا",IF(AB72>=70,"جيد",IF(AB72>=60,"متوسط",IF(AB72>=50,"مقبول","راسب"))))) -> 0
B75: 17 | C75: ايناس عبدالحسين محيل مهجر | D75: ذ | F75: =IF(E75>=90,"م",IF(E75>=80,"جـ جـ",IF(E75>=70,"جـ",IF(E75>=60,"ط",IF(E75>=50,"ل","ر"))))) -> 0 | H75: =IF(G75>=90,"م",IF(G75>=80,"جـ جـ",IF(G75>=70,"جـ",IF(G75>=60,"ط",IF(G75>=50,"ل","ر"))))) -> 0 | J75: =IF(I75>=90,"م",IF(I75>=80,"جـ جـ",IF(I75>=70,"جـ",IF(I75>=60,"ط",IF(I75>=50,"ل","ر"))))) -> 0 | L75: =IF(K75>=90,"م",IF(K75>=80,"جـ جـ",IF(K75>=70,"جـ",IF(K75>=60,"ط",IF(K75>=50,"ل","ر"))))) -> 0 | N75: =IF(M75>=90,"م",IF(M75>=80,"جـ جـ",IF(M75>=70,"جـ",IF(M75>=60,"ط",IF(M75>=50,"ل","ر"))))) -> 0 | P75: =IF(O75>=90,"م",IF(O75>=80,"جـ جـ",IF(O75>=70,"جـ",IF(O75>=60,"ط",IF(O75>=50,"ل","ر"))))) -> 0 | R75: =IF(Q75>=90,"م",IF(Q75>=80,"جـ جـ",IF(Q75>=70,"جـ",IF(Q75>=60,"ط",IF(Q75>=50,"ل","ر"))))) -> 0 | T75: =IF(S75>=90,"م",IF(S75>=80,"جـ جـ",IF(S75>=70,"جـ",IF(S75>=60,"ط",IF(S75>=50,"ل","ر"))))) -> 0 | V75: =IF(U75>=90,"م",IF(U75>=80,"جـ جـ",IF(U75>=70,"جـ",IF(U75>=60,"ط",IF(U75>=50,"ل","ر"))))) -> 0 | X75: =IF(W75>=90,"م",IF(W75>=80,"جـ جـ",IF(W75>=70,"جـ",IF(W75>=60,"ط",IF(W75>=50,"ل","ر"))))) -> 0 | Z75: =IF(Y75>=90,"م",IF(Y75>=80,"جـ جـ",IF(Y75>=70,"جـ",IF(Y75>=60,"ط",IF(Y75>=50,"ل","ر"))))) -> 0 | AA75: =IF(AND(E75>=50, G75>=50, I75>=50, K75>=50, M75>=50, O75>=50, Q75>=50, S75>=50, U75>=50, W75>=50, Y75>=50), "ناجح", "راسب") -> 0 | AB75: =(E75*7 + G75*2 + I75*6 + K75*7 + M75*4 + O75*2 + Q75*4 + S75*4 + U75*2 + W75*0) / (7 + 2 + 6 + 7 + 4 + 2 + 4 + 4 + 2 + 0) -> 0 | AC75: =IF(AB75>=90,"امتياز",IF(AB75>=80,"جيد جدا",IF(AB75>=70,"جيد",IF(AB75>=60,"متوسط",IF(AB75>=50,"مقبول","راسب"))))) -> 0
B78: 18 | C78: ايوب شمخي جابر حسب | D78: ذ | F78: =IF(E78>=90,"م",IF(E78>=80,"جـ جـ",IF(E78>=70,"جـ",IF(E78>=60,"ط",IF(E78>=50,"ل","ر"))))) -> 0 | H78: =IF(G78>=90,"م",IF(G78>=80,"جـ جـ",IF(G78>=70,"جـ",IF(G78>=60,"ط",IF(G78>=50,"ل","ر"))))) -> 0 | J78: =IF(I78>=90,"م",IF(I78>=80,"جـ جـ",IF(I78>=70,"جـ",IF(I78>=60,"ط",IF(I78>=50,"ل","ر"))))) -> 0 | L78: =IF(K78>=90,"م",IF(K78>=80,"جـ جـ",IF(K78>=70,"جـ",IF(K78>=60,"ط",IF(K78>=50,"ل","ر"))))) -> 0 | N78: =IF(M78>=90,"م",IF(M78>=80,"جـ جـ",IF(M78>=70,"جـ",IF(M78>=60,"ط",IF(M78>=50,"ل","ر"))))) -> 0 | P78: =IF(O78>=90,"م",IF(O78>=80,"جـ جـ",IF(O78>=70,"جـ",IF(O78>=60,"ط",IF(O78>=50,"ل","ر"))))) -> 0 | R78: =IF(Q78>=90,"م",IF(Q78>=80,"جـ جـ",IF(Q78>=70,"جـ",IF(Q78>=60,"ط",IF(Q78>=50,"ل","ر"))))) -> 0 | T78: =IF(S78>=90,"م",IF(S78>=80,"جـ جـ",IF(S78>=70,"جـ",IF(S78>=60,"ط",IF(S78>=50,"ل","ر"))))) -> 0 | V78: =IF(U78>=90,"م",IF(U78>=80,"جـ جـ",IF(U78>=70,"جـ",IF(U78>=60,"ط",IF(U78>=50,"ل","ر"))))) -> 0 | X78: =IF(W78>=90,"م",IF(W78>=80,"جـ جـ",IF(W78>=70,"جـ",IF(W78>=60,"ط",IF(W78>=50,"ل","ر"))))) -> 0 | Z78: =IF(Y78>=90,"م",IF(Y78>=80,"جـ جـ",IF(Y78>=70,"جـ",IF(Y78>=60,"ط",IF(Y78>=50,"ل","ر"))))) -> 0 | AA78: =IF(AND(E78>=50, G78>=50, I78>=50, K78>=50, M78>=50, O78>=50, Q78>=50, S78>=50, U78>=50, W78>=50, Y78>=50), "ناجح", "راسب") -> 0 | AB78: =(E78*7 + G78*2 + I78*6 + K78*7 + M78*4 + O78*2 + Q78*4 + S78*4 + U78*2 + W78*0) / (7 + 2 + 6 + 7 + 4 + 2 + 4 + 4 + 2 + 0) -> 0 | AC78: =IF(AB78>=90,"امتياز",IF(AB78>=80,"جيد جدا",IF(AB78>=70,"جيد",IF(AB78>=60,"متوسط",IF(AB78>=50,"مقبول","راسب"))))) -> 0
B81: 19 | C81: آيات كاظم جاسم محمد | D81: ذ | F81: =IF(E81>=90,"م",IF(E81>=80,"جـ جـ",IF(E81>=70,"جـ",IF(E81>=60,"ط",IF(E81>=50,"ل","ر"))))) -> 0 | H81: =IF(G81>=90,"م",IF(G81>=80,"جـ جـ",IF(G81>=70,"جـ",IF(G81>=60,"ط",IF(G81>=50,"ل","ر"))))) -> 0 | J81: =IF(I81>=90,"م",IF(I81>=80,"جـ جـ",IF(I81>=70,"جـ",IF(I81>=60,"ط",IF(I81>=50,"ل","ر"))))) -> 0 | L81: =IF(K81>=90,"م",IF(K81>=80,"جـ جـ",IF(K81>=70,"جـ",IF(K81>=60,"ط",IF(K81>=50,"ل","ر"))))) -> 0 | N81: =IF(M81>=90,"م",IF(M81>=80,"جـ جـ",IF(M81>=70,"جـ",IF(M81>=60,"ط",IF(M81>=50,"ل","ر"))))) -> 0 | P81: =IF(O81>=90,"م",IF(O81>=80,"جـ جـ",IF(O81>=70,"جـ",IF(O81>=60,"ط",IF(O81>=50,"ل","ر"))))) -> 0 | R81: =IF(Q81>=90,"م",IF(Q81>=80,"جـ جـ",IF(Q81>=70,"جـ",IF(Q81>=60,"ط",IF(Q81>=50,"ل","ر"))))) -> 0 | T81: =IF(S81>=90,"م",IF(S81>=80,"جـ جـ",IF(S81>=70,"جـ",IF(S81>=60,"ط",IF(S81>=50,"ل","ر"))))) -> 0 | V81: =IF(U81>=90,"م",IF(U81>=80,"جـ جـ",IF(U81>=70,"جـ",IF(U81>=60,"ط",IF(U81>=50,"ل","ر"))))) -> 0 | X81: =IF(W81>=90,"م",IF(W81>=80,"جـ جـ",IF(W81>=70,"جـ",IF(W81>=60,"ط",IF(W81>=50,"ل","ر"))))) -> 0 | Z81: =IF(Y81>=90,"م",IF(Y81>=80,"جـ جـ",IF(Y81>=70,"جـ",IF(Y81>=60,"ط",IF(Y81>=50,"ل","ر"))))) -> 0 | AA81: =IF(AND(E81>=50, G81>=50, I81>=50, K81>=50, M81>=50, O81>=50, Q81>=50, S81>=50, U81>=50, W81>=50, Y81>=50), "ناجح", "راسب") -> 0 | AB81: =(E81*7 + G81*2 + I81*6 + K81*7 + M81*4 + O81*2 + Q81*4 + S81*4 + U81*2 + W81*0) / (7 + 2 + 6 + 7 + 4 + 2 + 4 + 4 + 2 + 0) -> 0 | AC81: =IF(AB81>=90,"امتياز",IF(AB81>=80,"جيد جدا",IF(AB81>=70,"جيد",IF(AB81>=60,"متوسط",IF(AB81>=50,"مقبول","راسب"))))) -> 0
B84: 20 | C84: بتول عابدين حسين عيسى | D84: ذ | F84: =IF(E84>=90,"م",IF(E84>=80,"جـ جـ",IF(E84>=70,"جـ",IF(E84>=60,"ط",IF(E84>=50,"ل","ر"))))) -> 0 | H84: =IF(G84>=90,"م",IF(G84>=80,"جـ جـ",IF(G84>=70,"جـ",IF(G84>=60,"ط",IF(G84>=50,"ل","ر"))))) -> 0 | J84: =IF(I84>=90,"م",IF(I84>=80,"جـ جـ",IF(I84>=70,"جـ",IF(I84>=60,"ط",IF(I84>=50,"ل","ر"))))) -> 0 | L84: =IF(K84>=90,"م",IF(K84>=80,"جـ جـ",IF(K84>=70,"جـ",IF(K84>=60,"ط",IF(K84>=50,"ل","ر"))))) -> 0 | N84: =IF(M84>=90,"م",IF(M84>=80,"جـ جـ",IF(M84>=70,"جـ",IF(M84>=60,"ط",IF(M84>=50,"ل","ر"))))) -> 0 | P84: =IF(O84>=90,"م",IF(O84>=80,"جـ جـ",IF(O84>=70,"جـ",IF(O84>=60,"ط",IF(O84>=50,"ل","ر"))))) -> 0 | R84: =IF(Q84>=90,"م",IF(Q84>=80,"جـ جـ",IF(Q84>=70,"جـ",IF(Q84>=60,"ط",IF(Q84>=50,"ل","ر"))))) -> 0 | T84: =IF(S84>=90,"م",IF(S84>=80,"جـ جـ",IF(S84>=70,"جـ",IF(S84>=60,"ط",IF(S84>=50,"ل","ر"))))) -> 0 | V84: =IF(U84>=90,"م",IF(U84>=80,"جـ جـ",IF(U84>=70,"جـ",IF(U84>=60,"ط",IF(U84>=50,"ل","ر"))))) -> 0 | X84: =IF(W84>=90,"م",IF(W84>=80,"جـ جـ",IF(W84>=70,"جـ",IF(W84>=60,"ط",IF(W84>=50,"ل","ر"))))) -> 0 | Z84: =IF(Y84>=90,"م",IF(Y84>=80,"جـ جـ",IF(Y84>=70,"جـ",IF(Y84>=60,"ط",IF(Y84>=50,"ل","ر"))))) -> 0 | AA84: =IF(AND(E84>=50, G84>=50, I84>=50, K84>=50, M84>=50, O84>=50, Q84>=50, S84>=50, U84>=50, W84>=50, Y84>=50), "ناجح", "راسب") -> 0 | AB84: =(E84*7 + G84*2 + I84*6 + K84*7 + M84*4 + O84*2 + Q84*4 + S84*4 + U84*2 + W84*0) / (7 + 2 + 6 + 7 + 4 + 2 + 4 + 4 + 2 + 0) -> 0 | AC84: =IF(AB84>=90,"امتياز",IF(AB84>=80,"جيد جدا",IF(AB84>=70,"جيد",IF(AB84>=60,"متوسط",IF(AB84>=50,"مقبول","راسب"))))) -> 0
C88: اعضاء اللجنة الامتحانية:
...

Sheet Statistics
D5: 7 | E5: 2 | F5: 6 | G5: 7 | H5: 4 | I5: 2 | J5: 4 | K5: 4 | L5: 2 | M5: 0 | N5: 3
A6: ت | B6: اسم الطالب | C6: الجنس | D6: الكهربائية والمغناطيسية | E6: اللغة العربية | F6: الرياضيات | G6: الميكانيك | H6: علم النفس | I6: الحاسبات | J6: الحرارة وخواص المادة | K6: اسس التربية | L6: حقوق الانسان و الديمقراطية | M6: التربية الرياضية | N6: حقوق الانسان و الديمقراطية | O6: النتيجة | P6: المعدل | Q6: التقدير | R6: ت | S6: اسم الطالب | T6: الكهربائية والمغناطيسية | U6: اللغة العربية | V6: الرياضيات | W6: الميكانيك | X6: علم النفس | Y6: الحاسبات | Z6: الحرارة وخواص المادة | AA6: اسس التربية | AB6: حقوق الانسان و الديمقراطية | AC6: التربية الرياضية | AD6: حقوق الانسان و الديمقراطية | AE6: النتيجة | AF6: المعدل | AG6: التقدير | AH6: الملاحظات | AL6: الكهربائية والمغناطيسية | AM6: اللغة العربية | AN6: الرياضيات | AO6: الميكانيك | AP6: علم النفس | AQ6: الحاسبات | AR6: الحرارة وخواص المادة | AS6: اسس التربية | AT6: حقوق الانسان و الديمقراطية | AU6: التربية الرياضية | AV6: حقوق الانسان و الديمقراطية
A7: =MasterSheet!B7 -> 0 | B7: =MasterSheet!C7 -> 0 | C7: =MasterSheet!D7 -> 0 | D7: =MasterSheet!E7 -> 0 | E7: =MasterSheet!G7 -> 0 | F7: =MasterSheet!I7 -> 0 | G7: =MasterSheet!K7 -> 0 | H7: =MasterSheet!M7 -> 0 | I7: =MasterSheet!O7 -> 0 | J7: =MasterSheet!Q7 -> 0 | K7: =MasterSheet!S7 -> 0 | L7: =MasterSheet!U7 -> 0 | M7: =MasterSheet!W7 -> 0 | N7: =MasterSheet!Y7 -> 0 | O7: =MasterSheet!AA7 -> 0 | P7: =MasterSheet!AB7 -> 0 | Q7: =MasterSheet!AC7 -> 0 | R7: =A7 -> 0 | S7: =B7 -> 0 | T7: =IF(D7>=90,"امتياز",IF(D7>=80,"جـيد جدا",IF(D7>=70,"جـيد",IF(D7>=60,"متوسط",IF(D7>=50,"مقبول","راسب"))))) -> 0 | U7: =IF(E7>=90,"امتياز",IF(E7>=80,"جـيد جدا",IF(E7>=70,"جـيد",IF(E7>=60,"متوسط",IF(E7>=50,"مقبول","راسب"))))) -> 0 | V7: =IF(F7>=90,"امتياز",IF(F7>=80,"جـيد جدا",IF(F7>=70,"جـيد",IF(F7>=60,"متوسط",IF(F7>=50,"مقبول","راسب"))))) -> 0 | W7: =IF(G7>=90,"امتياز",IF(G7>=80,"جـيد جدا",IF(G7>=70,"جـيد",IF(G7>=60,"متوسط",IF(G7>=50,"مقبول","راسب"))))) -> 0 | X7: =IF(H7>=90,"امتياز",IF(H7>=80,"جـيد جدا",IF(H7>=70,"جـيد",IF(H7>=60,"متوسط",IF(H7>=50,"مقبول","راسب"))))) -> 0 | Y7: =IF(I7>=90,"امتياز",IF(I7>=80,"جـيد جدا",IF(I7>=70,"جـيد",IF(I7>=60,"متوسط",IF(I7>=50,"مقبول","راسب"))))) -> 0 | Z7: =IF(J7>=90,"امتياز",IF(J7>=80,"جـيد جدا",IF(J7>=70,"جـيد",IF(J7>=60,"متوسط",IF(J7>=50,"مقبول","راسب"))))) -> 0 | AA7: =IF(K7>=90,"امتياز",IF(K7>=80,"جـيد جدا",IF(K7>=70,"جـيد",IF(K7>=60,"متوسط",IF(K7>=50,"مقبول","راسب"))))) -> 0 | ... AD7: =IF(N7>=90,"امتياز",IF(N7>=80,"جـيد جدا",IF(N7>=70,"جـيد",IF(N7>=60,"متوسط",IF(N7>=50,"مقبول","راسب"))))) -> 0 | AE7: =MasterSheet!AA7 -> 0 | AF7: =MasterSheet!AB7 -> 0 | AG7: =MasterSheet!AC7 -> 0 | AL7: =IF(D7 >=50,"P","F") -> 0 | AM7: =IF(E7 >=50,"P","F") -> 0 | AN7: =IF(F7 >=50,"P","F") -> 0 | AO7: =IF(G7 >=50,"P","F") -> 0 | AP7: =IF(H7 >=50,"P","F") -> 0 | AQ7: =IF(I7 >=50,"P","F") -> 0 | AR7: =IF(J7 >=50,"P","F") -> 0 | AS7: =IF(K7 >=50,"P","F") -> 0 | ... AV7: =IF(N7 >=50,"P","F") -> 0 | AW7: =IF(AND(N7>=50,N7>=50,F7>=50,G7>=50,H7>=50,I7>=50,J7>=50,K7>=50,L7>=50,M7>=50),"P","F") -> 0
A8: =MasterSheet!B10 -> 0 | B8: =MasterSheet!C10 -> 0 | C8: =MasterSheet!D10 -> 0 | D8: =MasterSheet!E10 -> 0 | E8: =MasterSheet!G10 -> 0 | F8: =MasterSheet!I10 -> 0 | G8: =MasterSheet!K10 -> 0 | H8: =MasterSheet!M10 -> 0 | I8: =MasterSheet!O10 -> 0 | J8: =MasterSheet!Q10 -> 0 | K8: =MasterSheet!S10 -> 0 | L8: =MasterSheet!U10 -> 0 | M8: =MasterSheet!W10 -> 0 | N8: =MasterSheet!Y10 -> 0 | O8: =MasterSheet!AA10 -> 0 | P8: =MasterSheet!AB10 -> 0 | Q8: =MasterSheet!AC10 -> 0 | R8: =A8 -> 0 | S8: =B8 -> 0 | T8: =IF(D8>=90,"امتياز",IF(D8>=80,"جـيد جدا",IF(D8>=70,"جـيد",IF(D8>=60,"متوسط",IF(D8>=50,"مقبول","راسب"))))) -> 0 | U8: =IF(E8>=90,"امتياز",IF(E8>=80,"جـيد جدا",IF(E8>=70,"جـيد",IF(E8>=60,"متوسط",IF(E8>=50,"مقبول","راسب"))))) -> 0 | V8: =IF(F8>=90,"امتياز",IF(F8>=80,"جـيد جدا",IF(F8>=70,"جـيد",IF(F8>=60,"متوسط",IF(F8>=50,"مقبول","راسب"))))) -> 0 | W8: =IF(G8>=90,"امتياز",IF(G8>=80,"جـيد جدا",IF(G8>=70,"جـيد",IF(G8>=60,"متوسط",IF(G8>=50,"مقبول","راسب"))))) -> 0 | X8: =IF(H8>=90,"امتياز",IF(H8>=80,"جـيد جدا",IF(H8>=70,"جـيد",IF(H8>=60,"متوسط",IF(H8>=50,"مقبول","راسب"))))) -> 0 | Y8: =IF(I8>=90,"امتياز",IF(I8>=80,"جـيد جدا",IF(I8>=70,"جـيد",IF(I8>=60,"متوسط",IF(I8>=50,"مقبول","راسب"))))) -> 0 | Z8: =IF(J8>=90,"امتياز",IF(J8>=80,"جـيد جدا",IF(J8>=70,"جـيد",IF(J8>=60,"متوسط",IF(J8>=50,"مقبول","راسب"))))) -> 0 | AA8: =IF(K8>=90,"امتياز",IF(K8>=80,"جـيد جدا",IF(K8>=70,"جـيد",IF(K8>=60,"متوسط",IF(K8>=50,"مقبول","راسب"))))) -> 0 | ... AD8: =IF(N8>=90,"امتياز",IF(N8>=80,"جـيد جدا",IF(N8>=70,"جـيد",IF(N8>=60,"متوسط",IF(N8>=50,"مقبول","راسب"))))) -> 0 | AE8: =MasterSheet!AA10 -> 0 | AF8: =MasterSheet!AB10 -> 0 | AG8: =MasterSheet!AC10 -> 0 | AL8: =IF(D8 >=50,"P","F") -> 0 | AM8: =IF(E8 >=50,"P","F") -> 0 | AN8: =IF(F8 >=50,"P","F") -> 0 | AO8: =IF(G8 >=50,"P","F") -> 0 | AP8: =IF(H8 >=50,"P","F") -> 0 | AQ8: =IF(I8 >=50,"P","F") -> 0 | AR8: =IF(J8 >=50,"P","F") -> 0 | AS8: =IF(K8 >=50,"P","F") -> 0 | ... AV8: =IF(N8 >=50,"P","F") -> 0 | AW8: =IF(AND(N8>=50,N8>=50,F8>=50,G8>=50,H8>=50,I8>=50,J8>=50,K8>=50,L8>=50,M8>=50),"P","F") -> 0
A9: =MasterSheet!B13 -> 0 | B9: =MasterSheet!C13 -> 0 | C9: =MasterSheet!D13 -> 0 | D9: =MasterSheet!E13 -> 0 | E9: =MasterSheet!G13 -> 0 | F9: =MasterSheet!I13 -> 0 | G9: =MasterSheet!K13 -> 0 | H9: =MasterSheet!M13 -> 0 | I9: =MasterSheet!O13 -> 0 | J9: =MasterSheet!Q13 -> 0 | K9: =MasterSheet!S13 -> 0 | L9: =MasterSheet!U13 -> 0 | M9: =MasterSheet!W13 -> 0 | N9: =MasterSheet!Y13 -> 0 | O9: =MasterSheet!AA13 -> 0 | P9: =MasterSheet!AB13 -> 0 | Q9: =MasterSheet!AC13 -> 0 | R9: =A9 -> 0 | S9: =B9 -> 0 | T9: =IF(D9>=90,"امتياز",IF(D9>=80,"جـيد جدا",IF(D9>=70,"جـيد",IF(D9>=60,"متوسط",IF(D9>=50,"مقبول","راسب"))))) -> 0 | U9: =IF(E9>=90,"امتياز",IF(E9>=80,"جـيد جدا",IF(E9>=70,"جـيد",IF(E9>=60,"متوسط",IF(E9>=50,"مقبول","راسب"))))) -> 0 | V9: =IF(F9>=90,"امتياز",IF(F9>=80,"جـيد جدا",IF(F9>=70,"جـيد",IF(F9>=60,"متوسط",IF(F9>=50,"مقبول","راسب"))))) -> 0 | W9: =IF(G9>=90,"امتياز",IF(G9>=80,"جـيد جدا",IF(G9>=70,"جـيد",IF(G9>=60,"متوسط",IF(G9>=50,"مقبول","راسب"))))) -> 0 | X9: =IF(H9>=90,"امتياز",IF(H9>=80,"جـيد جدا",IF(H9>=70,"جـيد",IF(H9>=60,"متوسط",IF(H9>=50,"مقبول","راسب"))))) -> 0 | Y9: =IF(I9>=90,"امتياز",IF(I9>=80,"جـيد جدا",IF(I9>=70,"جـيد",IF(I9>=60,"متوسط",IF(I9>=50,"مقبول","راسب"))))) -> 0 | Z9: =IF(J9>=90,"امتياز",IF(J9>=80,"جـيد جدا",IF(J9>=70,"جـيد",IF(J9>=60,"متوسط",IF(J9>=50,"مقبول","راسب"))))) -> 0 | AA9: =IF(K9>=90,"امتياز",IF(K9>=80,"جـيد جدا",IF(K9>=70,"جـيد",IF(K9>=60,"متوسط",IF(K9>=50,"مقبول","راسب"))))) -> 0 | ... AD9: =IF(N9>=90,"امتياز",IF(N9>=80,"جـيد جدا",IF(N9>=70,"جـيد",IF(N9>=60,"متوسط",IF(N9>=50,"مقبول","راسب"))))) -> 0 | AE9: =MasterSheet!AA13 -> 0 | AF9: =MasterSheet!AB13 -> 0 | AG9: =MasterSheet!AC13 -> 0 | AL9: =IF(D9 >=50,"P","F") -> 0 | AM9: =IF(E9 >=50,"P","F") -> 0 | AN9: =IF(F9 >=50,"P","F") -> 0 | AO9: =IF(G9 >=50,"P","F") -> 0 | AP9: =IF(H9 >=50,"P","F") -> 0 | AQ9: =IF(I9 >=50,"P","F") -> 0 | AR9: =IF(J9 >=50,"P","F") -> 0 | AS9: =IF(K9 >=50,"P","F") -> 0 | ... AV9: =IF(N9 >=50,"P","F") -> 0 | AW9: =IF(AND(N9>=50,N9>=50,F9>=50,G9>=50,H9>=50,I9>=50,J9>=50,K9>=50,L9>=50,M9>=50),"P","F") -> 0
A10: =MasterSheet!B16 -> 0 | B10: =MasterSheet!C16 -> 0 | C10: =MasterSheet!D16 -> 0 | D10: =MasterSheet!E16 -> 0 | E10: =MasterSheet!G16 -> 0 | F10: =MasterSheet!I16 -> 0 | G10: =MasterSheet!K16 -> 0 | H10: =MasterSheet!M16 -> 0 | I10: =MasterSheet!O16 -> 0 | J10: =MasterSheet!Q16 -> 0 | K10: =MasterSheet!S16 -> 0 | L10: =MasterSheet!U16 -> 0 | M10: =MasterSheet!W16 -> 0 | N10: =MasterSheet!Y16 -> 0 | O10: =MasterSheet!AA16 -> 0 | P10: =MasterSheet!AB16 -> 0 | Q10: =MasterSheet!AC16 -> 0 | R10: =A10 -> 0 | S10: =B10 -> 0 | T10: =IF(D10>=90,"امتياز",IF(D10>=80,"جـيد جدا",IF(D10>=70,"جـيد",IF(D10>=60,"متوسط",IF(D10>=50,"مقبول","راسب"))))) -> 0 | U10: =IF(E10>=90,"امتياز",IF(E10>=80,"جـيد جدا",IF(E10>=70,"جـيد",IF(E10>=60,"متوسط",IF(E10>=50,"مقبول","راسب"))))) -> 0 | V10: =IF(F10>=90,"امتياز",IF(F10>=80,"جـيد جدا",IF(F10>=70,"جـيد",IF(F10>=60,"متوسط",IF(F10>=50,"مقبول","راسب"))))) -> 0 | W10: =IF(G10>=90,"امتياز",IF(G10>=80,"جـيد جدا",IF(G10>=70,"جـيد",IF(G10>=60,"متوسط",IF(G10>=50,"مقبول","راسب"))))) -> 0 | X10: =IF(H10>=90,"امتياز",IF(H10>=80,"جـيد جدا",IF(H10>=70,"جـيد",IF(H10>=60,"متوسط",IF(H10>=50,"مقبول","راسب"))))) -> 0 | Y10: =IF(I10>=90,"امتياز",IF(I10>=80,"جـيد جدا",IF(I10>=70,"جـيد",IF(I10>=60,"متوسط",IF(I10>=50,"مقبول","راسب"))))) -> 0 | Z10: =IF(J10>=90,"امتياز",IF(J10>=80,"جـيد جدا",IF(J10>=70,"جـيد",IF(J10>=60,"متوسط",IF(J10>=50,"مقبول","راسب"))))) -> 0 | AA10: =IF(K10>=90,"امتياز",IF(K10>=80,"جـيد جدا",IF(K10>=70,"جـيد",IF(K10>=60,"متوسط",IF(K10>=50,"مقبول","راسب"))))) -> 0 | ... AD10: =IF(N10>=90,"امتياز",IF(N10>=80,"جـيد جدا",IF(N10>=70,"جـيد",IF(N10>=60,"متوسط",IF(N10>=50,"مقبول","راسب"))))) -> 0 | AE10: =MasterSheet!AA16 -> 0 | AF10: =MasterSheet!AB16 -> 0 | AG10: =MasterSheet!AC16 -> 0 | AL10: =IF(D10 >=50,"P","F") -> 0 | AM10: =IF(E10 >=50,"P","F") -> 0 | AN10: =IF(F10 >=50,"P","F") -> 0 | AO10: =IF(G10 >=50,"P","F") -> 0 | AP10: =IF(H10 >=50,"P","F") -> 0 | AQ10: =IF(I10 >=50,"P","F") -> 0 | AR10: =IF(J10 >=50,"P","F") -> 0 | AS10: =IF(K10 >=50,"P","F") -> 0 | ... AV10: =IF(N10 >=50,"P","F") -> 0 | AW10: =IF(AND(N10>=50,N10>=50,F10>=50,G10>=50,H10>=50,I10>=50,J10>=50,K10>=50,L10>=50,M10>=50),"P","F") -> 0
A11: =MasterSheet!B19 -> 0 | B11: =MasterSheet!C19 -> 0 | C11: =MasterSheet!D19 -> 0 | D11: =MasterSheet!E19 -> 0 | E11: =MasterSheet!G19 -> 0 | F11: =MasterSheet!I19 -> 0 | G11: =MasterSheet!K19 -> 0 | H11: =MasterSheet!M19 -> 0 | I11: =MasterSheet!O19 -> 0 | J11: =MasterSheet!Q19 -> 0 | K11: =MasterSheet!S19 -> 0 | L11: =MasterSheet!U19 -> 0 | M11: =MasterSheet!W19 -> 0 | N11: =MasterSheet!Y19 -> 0 | O11: =MasterSheet!AA19 -> 0 | P11: =MasterSheet!AB19 -> 0 | Q11: =MasterSheet!AC19 -> 0 | R11: =A11 -> 0 | S11: =B11 -> 0 | T11: =IF(D11>=90,"امتياز",IF(D11>=80,"جـيد جدا",IF(D11>=70,"جـيد",IF(D11>=60,"متوسط",IF(D11>=50,"مقبول","راسب"))))) -> 0 | U11: =IF(E11>=90,"امتياز",IF(E11>=80,"جـيد جدا",IF(E11>=70,"جـيد",IF(E11>=60,"متوسط",IF(E11>=50,"مقبول","راسب"))))) -> 0 | V11: =IF(F11>=90,"امتياز",IF(F11>=80,"جـيد جدا",IF(F11>=70,"جـيد",IF(F11>=60,"متوسط",IF(F11>=50,"مقبول","راسب"))))) -> 0 | W11: =IF(G11>=90,"امتياز",IF(G11>=80,"جـيد جدا",IF(G11>=70,"جـيد",IF(G11>=60,"متوسط",IF(G11>=50,"مقبول","راسب"))))) -> 0 | X11: =IF(H11>=90,"امتياز",IF(H11>=80,"جـيد جدا",IF(H11>=70,"جـيد",IF(H11>=60,"متوسط",IF(H11>=50,"مقبول","راسب"))))) -> 0 | Y11: =IF(I11>=90,"امتياز",IF(I11>=80,"جـيد جدا",IF(I11>=70,"جـيد",IF(I11>=60,"متوسط",IF(I11>=50,"مقبول","راسب"))))) -> 0 | Z11: =IF(J11>=90,"امتياز",IF(J11>=80,"جـيد جدا",IF(J11>=70,"جـيد",IF(J11>=60,"متوسط",IF(J11>=50,"مقبول","راسب"))))) -> 0 | AA11: =IF(K11>=90,"امتياز",IF(K11>=80,"جـيد جدا",IF(K11>=70,"جـيد",IF(K11>=60,"متوسط",IF(K11>=50,"مقبول","راسب"))))) -> 0 | ... AD11: =IF(N11>=90,"امتياز",IF(N11>=80,"جـيد جدا",IF(N11>=70,"جـيد",IF(N11>=60,"متوسط",IF(N11>=50,"مقبول","راسب"))))) -> 0 | AE11: =MasterSheet!AA19 -> 0 | AF11: =MasterSheet!AB19 -> 0 | AG11: =MasterSheet!AC19 -> 0 | AL11: =IF(D11 >=50,"P","F") -> 0 | AM11: =IF(E11 >=50,"P","F") -> 0 | AN11: =IF(F11 >=50,"P","F") -> 0 | AO11: =IF(G11 >=50,"P","F") -> 0 | AP11: =IF(H11 >=50,"P","F") -> 0 | AQ11: =IF(I11 >=50,"P","F") -> 0 | AR11: =IF(J11 >=50,"P","F") -> 0 | AS11: =IF(K11 >=50,"P","F") -> 0 | ... AV11: =IF(N11 >=50,"P","F") -> 0 | AW11: =IF(AND(N11>=50,N11>=50,F11>=50,G11>=50,H11>=50,I11>=50,J11>=50,K11>=50,L11>=50,M11>=50),"P","F") -> 0
A12: =MasterSheet!B22 -> 0 | B12: =MasterSheet!C22 -> 0 | C12: =MasterSheet!D22 -> 0 | D12: =MasterSheet!E22 -> 0 | E12: =MasterSheet!G22 -> 0 | F12: =MasterSheet!I22 -> 0 | G12: =MasterSheet!K22 -> 0 | H12: =MasterSheet!M22 -> 0 | I12: =MasterSheet!O22 -> 0 | J12: =MasterSheet!Q22 -> 0 | K12: =MasterSheet!S22 -> 0 | L12: =MasterSheet!U22 -> 0 | M12: =MasterSheet!W22 -> 0 | N12: =MasterSheet!Y22 -> 0 | O12: =MasterSheet!AA22 -> 0 | P12: =MasterSheet!AB22 -> 0 | Q12: =MasterSheet!AC22 -> 0 | R12: =A12 -> 0 | S12: =B12 -> 0 | T12: =IF(D12>=90,"امتياز",IF(D12>=80,"جـيد جدا",IF(D12>=70,"جـيد",IF(D12>=60,"متوسط",IF(D12>=50,"مقبول","راسب"))))) -> 0 | U12: =IF(E12>=90,"امتياز",IF(E12>=80,"جـيد جدا",IF(E12>=70,"جـيد",IF(E12>=60,"متوسط",IF(E12>=50,"مقبول","راسب"))))) -> 0 | V12: =IF(F12>=90,"امتياز",IF(F12>=80,"جـيد جدا",IF(F12>=70,"جـيد",IF(F12>=60,"متوسط",IF(F12>=50,"مقبول","راسب"))))) -> 0 | W12: =IF(G12>=90,"امتياز",IF(G12>=80,"جـيد جدا",IF(G12>=70,"جـيد",IF(G12>=60,"متوسط",IF(G12>=50,"مقبول","راسب"))))) -> 0 | X12: =IF(H12>=90,"امتياز",IF(H12>=80,"جـيد جدا",IF(H12>=70,"جـيد",IF(H12>=60,"متوسط",IF(H12>=50,"مقبول","راسب"))))) -> 0 | Y12: =IF(I12>=90,"امتياز",IF(I12>=80,"جـيد جدا",IF(I12>=70,"جـيد",IF(I12>=60,"متوسط",IF(I12>=50,"مقبول","راسب"))))) -> 0 | Z12: =IF(J12>=90,"امتياز",IF(J12>=80,"جـيد جدا",IF(J12>=70,"جـيد",IF(J12>=60,"متوسط",IF(J12>=50,"مقبول","راسب"))))) -> 0 | AA12: =IF(K12>=90,"امتياز",IF(K12>=80,"جـيد جدا",IF(K12>=70,"جـيد",IF(K12>=60,"متوسط",IF(K12>=50,"مقبول","راسب"))))) -> 0 | ... AD12: =IF(N12>=90,"امتياز",IF(N12>=80,"جـيد جدا",IF(N12>=70,"جـيد",IF(N12>=60,"متوسط",IF(N12>=50,"مقبول","راسب"))))) -> 0 | AE12: =MasterSheet!AA22 -> 0 | AF12: =MasterSheet!AB22 -> 0 | AG12: =MasterSheet!AC22 -> 0 | AL12: =IF(D12 >=50,"P","F") -> 0 | AM12: =IF(E12 >=50,"P","F") -> 0 | AN12: =IF(F12 >=50,"P","F") -> 0 | AO12: =IF(G12 >=50,"P","F") -> 0 | AP12: =IF(H12 >=50,"P","F") -> 0 | AQ12: =IF(I12 >=50,"P","F") -> 0 | AR12: =IF(J12 >=50,"P","F") -> 0 | AS12: =IF(K12 >=50,"P","F") -> 0 | ... AV12: =IF(N12 >=50,"P","F") -> 0 | AW12: =IF(AND(N12>=50,N12>=50,F12>=50,G12>=50,H12>=50,I12>=50,J12>=50,K12>=50,L12>=50,M12>=50),"P","F") -> 0
A13: =MasterSheet!B25 -> 0 | B13: =MasterSheet!C25 -> 0 | C13: =MasterSheet!D25 -> 0 | D13: =MasterSheet!E25 -> 0 | E13: =MasterSheet!G25 -> 0 | F13: =MasterSheet!I25 -> 0 | G13: =MasterSheet!K25 -> 0 | H13: =MasterSheet!M25 -> 0 | I13: =MasterSheet!O25 -> 0 | J13: =MasterSheet!Q25 -> 0 | K13: =MasterSheet!S25 -> 0 | L13: =MasterSheet!U25 -> 0 | M13: =MasterSheet!W25 -> 0 | N13: =MasterSheet!Y25 -> 0 | O13: =MasterSheet!AA25 -> 0 | P13: =MasterSheet!AB25 -> 0 | Q13: =MasterSheet!AC25 -> 0 | R13: =A13 -> 0 | S13: =B13 -> 0 | T13: =IF(D13>=90,"امتياز",IF(D13>=80,"جـيد جدا",IF(D13>=70,"جـيد",IF(D13>=60,"متوسط",IF(D13>=50,"مقبول","راسب"))))) -> 0 | U13: =IF(E13>=90,"امتياز",IF(E13>=80,"جـيد جدا",IF(E13>=70,"جـيد",IF(E13>=60,"متوسط",IF(E13>=50,"مقبول","راسب"))))) -> 0 | V13: =IF(F13>=90,"امتياز",IF(F13>=80,"جـيد جدا",IF(F13>=70,"جـيد",IF(F13>=60,"متوسط",IF(F13>=50,"مقبول","راسب"))))) -> 0 | W13: =IF(G13>=90,"امتياز",IF(G13>=80,"جـيد جدا",IF(G13>=70,"جـيد",IF(G13>=60,"متوسط",IF(G13>=50,"مقبول","راسب"))))) -> 0 | X13: =IF(H13>=90,"امتياز",IF(H13>=80,"جـيد جدا",IF(H13>=70,"جـيد",IF(H13>=60,"متوسط",IF(H13>=50,"مقبول","راسب"))))) -> 0 | Y13: =IF(I13>=90,"امتياز",IF(I13>=80,"جـيد جدا",IF(I13>=70,"جـيد",IF(I13>=60,"متوسط",IF(I13>=50,"مقبول","راسب"))))) -> 0 | Z13: =IF(J13>=90,"امتياز",IF(J13>=80,"جـيد جدا",IF(J13>=70,"جـيد",IF(J13>=60,"متوسط",IF(J13>=50,"مقبول","راسب"))))) -> 0 | AA13: =IF(K13>=90,"امتياز",IF(K13>=80,"جـيد جدا",IF(K13>=70,"جـيد",IF(K13>=60,"متوسط",IF(K13>=50,"مقبول","راسب"))))) -> 0 | ... AD13: =IF(N13>=90,"امتياز",IF(N13>=80,"جـيد جدا",IF(N13>=70,"جـيد",IF(N13>=60,"متوسط",IF(N13>=50,"مقبول","راسب"))))) -> 0 | AE13: =MasterSheet!AA25 -> 0 | AF13: =MasterSheet!AB25 -> 0 | AG13: =MasterSheet!AC25 -> 0 | AL13: =IF(D13 >=50,"P","F") -> 0 | AM13: =IF(E13 >=50,"P","F") -> 0 | AN13: =IF(F13 >=50,"P","F") -> 0 | AO13: =IF(G13 >=50,"P","F") -> 0 | AP13: =IF(H13 >=50,"P","F") -> 0 | AQ13: =IF(I13 >=50,"P","F") -> 0 | AR13: =IF(J13 >=50,"P","F") -> 0 | AS13: =IF(K13 >=50,"P","F") -> 0 | ... AV13: =IF(N13 >=50,"P","F") -> 0 | AW13: =IF(AND(N13>=50,N13>=50,F13>=50,G13>=50,H13>=50,I13>=50,J13>=50,K13>=50,L13>=50,M13>=50),"P","F") -> 0
A14: =MasterSheet!B28 -> 0 | B14: =MasterSheet!C28 -> 0 | C14: =MasterSheet!D28 -> 0 | D14: =MasterSheet!E28 -> 0 | E14: =MasterSheet!G28 -> 0 | F14: =MasterSheet!I28 -> 0 | G14: =MasterSheet!K28 -> 0 | H14: =MasterSheet!M28 -> 0 | I14: =MasterSheet!O28 -> 0 | J14: =MasterSheet!Q28 -> 0 | K14: =MasterSheet!S28 -> 0 | L14: =MasterSheet!U28 -> 0 | M14: =MasterSheet!W28 -> 0 | N14: =MasterSheet!Y28 -> 0 | O14: =MasterSheet!AA28 -> 0 | P14: =MasterSheet!AB28 -> 0 | Q14: =MasterSheet!AC28 -> 0 | R14: =A14 -> 0 | S14: =B14 -> 0 | T14: =IF(D14>=90,"امتياز",IF(D14>=80,"جـيد جدا",IF(D14>=70,"جـيد",IF(D14>=60,"متوسط",IF(D14>=50,"مقبول","راسب"))))) -> 0 | U14: =IF(E14>=90,"امتياز",IF(E14>=80,"جـيد جدا",IF(E14>=70,"جـيد",IF(E14>=60,"متوسط",IF(E14>=50,"مقبول","راسب"))))) -> 0 | V14: =IF(F14>=90,"امتياز",IF(F14>=80,"جـيد جدا",IF(F14>=70,"جـيد",IF(F14>=60,"متوسط",IF(F14>=50,"مقبول","راسب"))))) -> 0 | W14: =IF(G14>=90,"امتياز",IF(G14>=80,"جـيد جدا",IF(G14>=70,"جـيد",IF(G14>=60,"متوسط",IF(G14>=50,"مقبول","راسب"))))) -> 0 | X14: =IF(H14>=90,"امتياز",IF(H14>=80,"جـيد جدا",IF(H14>=70,"جـيد",IF(H14>=60,"متوسط",IF(H14>=50,"مقبول","راسب"))))) -> 0 | Y14: =IF(I14>=90,"امتياز",IF(I14>=80,"جـيد جدا",IF(I14>=70,"جـيد",IF(I14>=60,"متوسط",IF(I14>=50,"مقبول","راسب"))))) -> 0 | Z14: =IF(J14>=90,"امتياز",IF(J14>=80,"جـيد جدا",IF(J14>=70,"جـيد",IF(J14>=60,"متوسط",IF(J14>=50,"مقبول","راسب"))))) -> 0 | AA14: =IF(K14>=90,"امتياز",IF(K14>=80,"جـيد جدا",IF(K14>=70,"جـيد",IF(K14>=60,"متوسط",IF(K14>=50,"مقبول","راسب"))))) -> 0 | ... AD14: =IF(N14>=90,"امتياز",IF(N14>=80,"جـيد جدا",IF(N14>=70,"جـيد",IF(N14>=60,"متوسط",IF(N14>=50,"مقبول","راسب"))))) -> 0 | AE14: =MasterSheet!AA28 -> 0 | AF14: =MasterSheet!AB28 -> 0 | AG14: =MasterSheet!AC28 -> 0 | AL14: =IF(D14 >=50,"P","F") -> 0 | AM14: =IF(E14 >=50,"P","F") -> 0 | AN14: =IF(F14 >=50,"P","F") -> 0 | AO14: =IF(G14 >=50,"P","F") -> 0 | AP14: =IF(H14 >=50,"P","F") -> 0 | AQ14: =IF(I14 >=50,"P","F") -> 0 | AR14: =IF(J14 >=50,"P","F") -> 0 | AS14: =IF(K14 >=50,"P","F") -> 0 | ... AV14: =IF(N14 >=50,"P","F") -> 0 | AW14: =IF(AND(N14>=50,N14>=50,F14>=50,G14>=50,H14>=50,I14>=50,J14>=50,K14>=50,L14>=50,M14>=50),"P","F") -> 0
A15: =MasterSheet!B31 -> 0 | B15: =MasterSheet!C31 -> 0 | C15: =MasterSheet!D31 -> 0 | D15: =MasterSheet!E31 -> 0 | E15: =MasterSheet!G31 -> 0 | F15: =MasterSheet!I31 -> 0 | G15: =MasterSheet!K31 -> 0 | H15: =MasterSheet!M31 -> 0 | I15: =MasterSheet!O31 -> 0 | J15: =MasterSheet!Q31 -> 0 | K15: =MasterSheet!S31 -> 0 | L15: =MasterSheet!U31 -> 0 | M15: =MasterSheet!W31 -> 0 | N15: =MasterSheet!Y31 -> 0 | O15: =MasterSheet!AA31 -> 0 | P15: =MasterSheet!AB31 -> 0 | Q15: =MasterSheet!AC31 -> 0 | R15: =A15 -> 0 | S15: =B15 -> 0 | T15: =IF(D15>=90,"امتياز",IF(D15>=80,"جـيد جدا",IF(D15>=70,"جـيد",IF(D15>=60,"متوسط",IF(D15>=50,"مقبول","راسب"))))) -> 0 | U15: =IF(E15>=90,"امتياز",IF(E15>=80,"جـيد جدا",IF(E15>=70,"جـيد",IF(E15>=60,"متوسط",IF(E15>=50,"مقبول","راسب"))))) -> 0 | V15: =IF(F15>=90,"امتياز",IF(F15>=80,"جـيد جدا",IF(F15>=70,"جـيد",IF(F15>=60,"متوسط",IF(F15>=50,"مقبول","راسب"))))) -> 0 | W15: =IF(G15>=90,"امتياز",IF(G15>=80,"جـيد جدا",IF(G15>=70,"جـيد",IF(G15>=60,"متوسط",IF(G15>=50,"مقبول","راسب"))))) -> 0 | X15: =IF(H15>=90,"امتياز",IF(H15>=80,"جـيد جدا",IF(H15>=70,"جـيد",IF(H15>=60,"متوسط",IF(H15>=50,"مقبول","راسب"))))) -> 0 | Y15: =IF(I15>=90,"امتياز",IF(I15>=80,"جـيد جدا",IF(I15>=70,"جـيد",IF(I15>=60,"متوسط",IF(I15>=50,"مقبول","راسب"))))) -> 0 | Z15: =IF(J15>=90,"امتياز",IF(J15>=80,"جـيد جدا",IF(J15>=70,"جـيد",IF(J15>=60,"متوسط",IF(J15>=50,"مقبول","راسب"))))) -> 0 | AA15: =IF(K15>=90,"امتياز",IF(K15>=80,"جـيد جدا",IF(K15>=70,"جـيد",IF(K15>=60,"متوسط",IF(K15>=50,"مقبول","راسب"))))) -> 0 | ... AD15: =IF(N15>=90,"امتياز",IF(N15>=80,"جـيد جدا",IF(N15>=70,"جـيد",IF(N15>=60,"متوسط",IF(N15>=50,"مقبول","راسب"))))) -> 0 | AE15: =MasterSheet!AA31 -> 0 | AF15: =MasterSheet!AB31 -> 0 | AG15: =MasterSheet!AC31 -> 0 | AL15: =IF(D15 >=50,"P","F") -> 0 | AM15: =IF(E15 >=50,"P","F") -> 0 | AN15: =IF(F15 >=50,"P","F") -> 0 | AO15: =IF(G15 >=50,"P","F") -> 0 | AP15: =IF(H15 >=50,"P","F") -> 0 | AQ15: =IF(I15 >=50,"P","F") -> 0 | AR15: =IF(J15 >=50,"P","F") -> 0 | AS15: =IF(K15 >=50,"P","F") -> 0 | ... AV15: =IF(N15 >=50,"P","F") -> 0 | AW15: =IF(AND(N15>=50,N15>=50,F15>=50,G15>=50,H15>=50,I15>=50,J15>=50,K15>=50,L15>=50,M15>=50),"P","F") -> 0
A16: =MasterSheet!B34 -> 0 | B16: =MasterSheet!C34 -> 0 | C16: =MasterSheet!D34 -> 0 | D16: =MasterSheet!E34 -> 0 | E16: =MasterSheet!G34 -> 0 | F16: =MasterSheet!I34 -> 0 | G16: =MasterSheet!K34 -> 0 | H16: =MasterSheet!M34 -> 0 | I16: =MasterSheet!O34 -> 0 | J16: =MasterSheet!Q34 -> 0 | K16: =MasterSheet!S34 -> 0 | L16: =MasterSheet!U34 -> 0 | M16: =MasterSheet!W34 -> 0 | N16: =MasterSheet!Y34 -> 0 | O16: =MasterSheet!AA34 -> 0 | P16: =MasterSheet!AB34 -> 0 | Q16: =MasterSheet!AC34 -> 0 | R16: =A16 -> 0 | S16: =B16 -> 0 | T16: =IF(D16>=90,"امتياز",IF(D16>=80,"جـيد جدا",IF(D16>=70,"جـيد",IF(D16>=60,"متوسط",IF(D16>=50,"مقبول","راسب"))))) -> 0 | U16: =IF(E16>=90,"امتياز",IF(E16>=80,"جـيد جدا",IF(E16>=70,"جـيد",IF(E16>=60,"متوسط",IF(E16>=50,"مقبول","راسب"))))) -> 0 | V16: =IF(F16>=90,"امتياز",IF(F16>=80,"جـيد جدا",IF(F16>=70,"جـيد",IF(F16>=60,"متوسط",IF(F16>=50,"مقبول","راسب"))))) -> 0 | W16: =IF(G16>=90,"امتياز",IF(G16>=80,"جـيد جدا",IF(G16>=70,"جـيد",IF(G16>=60,"متوسط",IF(G16>=50,"مقبول","راسب"))))) -> 0 | X16: =IF(H16>=90,"امتياز",IF(H16>=80,"جـيد جدا",IF(H16>=70,"جـيد",IF(H16>=60,"متوسط",IF(H16>=50,"مقبول","راسب"))))) -> 0 | Y16: =IF(I16>=90,"امتياز",IF(I16>=80,"جـيد جدا",IF(I16>=70,"جـيد",IF(I16>=60,"متوسط",IF(I16>=50,"مقبول","راسب"))))) -> 0 | Z16: =IF(J16>=90,"امتياز",IF(J16>=80,"جـيد جدا",IF(J16>=70,"جـيد",IF(J16>=60,"متوسط",IF(J16>=50,"مقبول","راسب"))))) -> 0 | AA16: =IF(K16>=90,"امتياز",IF(K16>=80,"جـيد جدا",IF(K16>=70,"جـيد",IF(K16>=60,"متوسط",IF(K16>=50,"مقبول","راسب"))))) -> 0 | ... AD16: =IF(N16>=90,"امتياز",IF(N16>=80,"جـيد جدا",IF(N16>=70,"جـيد",IF(N16>=60,"متوسط",IF(N16>=50,"مقبول","راسب"))))) -> 0 | AE16: =MasterSheet!AA34 -> 0 | AF16: =MasterSheet!AB34 -> 0 | AG16: =MasterSheet!AC34 -> 0 | AL16: =IF(D16 >=50,"P","F") -> 0 | AM16: =IF(E16 >=50,"P","F") -> 0 | AN16: =IF(F16 >=50,"P","F") -> 0 | AO16: =IF(G16 >=50,"P","F") -> 0 | AP16: =IF(H16 >=50,"P","F") -> 0 | AQ16: =IF(I16 >=50,"P","F") -> 0 | AR16: =IF(J16 >=50,"P","F") -> 0 | AS16: =IF(K16 >=50,"P","F") -> 0 | ... AV16: =IF(N16 >=50,"P","F") -> 0 | AW16: =IF(AND(N16>=50,N16>=50,F16>=50,G16>=50,H16>=50,I16>=50,J16>=50,K16>=50,L16>=50,M16>=50),"P","F") -> 0
A17: =MasterSheet!B57 -> 0 | B17: =MasterSheet!C57 -> 0 | C17: =MasterSheet!D57 -> 0 | D17: =MasterSheet!E57 -> 0 | E17: =MasterSheet!G57 -> 0 | F17: =MasterSheet!I57 -> 0 | G17: =MasterSheet!K57 -> 0 | H17: =MasterSheet!M57 -> 0 | I17: =MasterSheet!O57 -> 0 | J17: =MasterSheet!Q57 -> 0 | K17: =MasterSheet!S57 -> 0 | L17: =MasterSheet!U57 -> 0 | M17: =MasterSheet!W57 -> 0 | N17: =MasterSheet!Y57 -> 0 | O17: =MasterSheet!AA57 -> 0 | P17: =MasterSheet!AB57 -> 0 | Q17: =MasterSheet!AC57 -> 0 | R17: =A17 -> 0 | S17: =B17 -> 0 | T17: =IF(D17>=90,"امتياز",IF(D17>=80,"جـيد جدا",IF(D17>=70,"جـيد",IF(D17>=60,"متوسط",IF(D17>=50,"مقبول","راسب"))))) -> 0 | U17: =IF(E17>=90,"امتياز",IF(E17>=80,"جـيد جدا",IF(E17>=70,"جـيد",IF(E17>=60,"متوسط",IF(E17>=50,"مقبول","راسب"))))) -> 0 | V17: =IF(F17>=90,"امتياز",IF(F17>=80,"جـيد جدا",IF(F17>=70,"جـيد",IF(F17>=60,"متوسط",IF(F17>=50,"مقبول","راسب"))))) -> 0 | W17: =IF(G17>=90,"امتياز",IF(G17>=80,"جـيد جدا",IF(G17>=70,"جـيد",IF(G17>=60,"متوسط",IF(G17>=50,"مقبول","راسب"))))) -> 0 | X17: =IF(H17>=90,"امتياز",IF(H17>=80,"جـيد جدا",IF(H17>=70,"جـيد",IF(H17>=60,"متوسط",IF(H17>=50,"مقبول","راسب"))))) -> 0 | Y17: =IF(I17>=90,"امتياز",IF(I17>=80,"جـيد جدا",IF(I17>=70,"جـيد",IF(I17>=60,"متوسط",IF(I17>=50,"مقبول","راسب"))))) -> 0 | Z17: =IF(J17>=90,"امتياز",IF(J17>=80,"جـيد جدا",IF(J17>=70,"جـيد",IF(J17>=60,"متوسط",IF(J17>=50,"مقبول","راسب"))))) -> 0 | AA17: =IF(K17>=90,"امتياز",IF(K17>=80,"جـيد جدا",IF(K17>=70,"جـيد",IF(K17>=60,"متوسط",IF(K17>=50,"مقبول","راسب"))))) -> 0 | ... AD17: =IF(N17>=90,"امتياز",IF(N17>=80,"جـيد جدا",IF(N17>=70,"جـيد",IF(N17>=60,"متوسط",IF(N17>=50,"مقبول","راسب"))))) -> 0 | AE17: =MasterSheet!AA57 -> 0 | AF17: =MasterSheet!AB57 -> 0 | AG17: =MasterSheet!AC57 -> 0 | AL17: =IF(D17 >=50,"P","F") -> 0 | AM17: =IF(E17 >=50,"P","F") -> 0 | AN17: =IF(F17 >=50,"P","F") -> 0 | AO17: =IF(G17 >=50,"P","F") -> 0 | AP17: =IF(H17 >=50,"P","F") -> 0 | AQ17: =IF(I17 >=50,"P","F") -> 0 | AR17: =IF(J17 >=50,"P","F") -> 0 | AS17: =IF(K17 >=50,"P","F") -> 0 | ... AV17: =IF(N17 >=50,"P","F") -> 0 | AW17: =IF(AND(N17>=50,N17>=50,F17>=50,G17>=50,H17>=50,I17>=50,J17>=50,K17>=50,L17>=50,M17>=50),"P","F") -> 0
